Workbook

Sheet 8D Form_v1
G2: 1. Recurring failure
G3: 2. Pass through failure
G4: 3. Instructions
G5: 4. Process parameters
G6: 5. Test Equipment
G7: 6. Check the checker
G8: 7. TPM
G9: 8. Tools
G10: 9. Restart
G11: 10. Labeling
G12: 11. Rework, scrap
G13: 12. Dropped parts
... G15: 14. Remaining items
B16: 1-3-10 Rule (calendar days)
B17: 1st day: intemediate report to customer: Effective containment action (8D: head data, D1, D2 and D3 completed) 3rd day: intemediate report to customer: Root cause investigation, Ishikawa, 5W (8D: D4 completed) 10th day: Corrective actions implemented (8D: D5, D6, D7, D8 completed)
H18: 8D report | AA18: D2 - Failure Visualization
H23: Complete all fields. Use n/a if not applicable. Add lines, information and fields as necessary to completely present your problem solving activities.
U25: 8D started on: | V25: 2025.06.10 | Z25: Attachment
J26: Complaint No.: | U26: Intermediate report: | Z26: Attachment No.
J27: Concession No.: | U27: Final report:
B29: Header data
B30: 8D-Title: | F30: Shrot brush length | N30: Part number: | R30: 3134320709
B31: Complaint type/mode: /0-km, Field, Production, Customer, Logistic/ | F31: Eckerle in line | N31: Part name: | R31: Carbon Brush GBM
B32: Supplier No.: | N32: Eckerle Production plant: | R32: Eckerle Automotive Kft
B33: Supplier name: | F33: AVO Carbon Korea | N33: Supplier delivery No. / Shipment date : | R33: AVO25019 / 2025.02.11
B34: Contact Person at Eckerle: | H34: Suba - Kis Anett | U34: Telephone: | V34: +36.30.699.5791
B35: Business Address: | H35: 6200 Kiskőrös, Dózsa György út 44 | U35: Email: | V35: Anett.Kis@hu.eckerle-gruppe.com
B36: Contact Person at Supplier: | H36: Jaeseok Lee | U36: Telephone: | V36: +53.610.6215
B37: Business Address: | H37: 306 Nongong-ro, Dalseong-gun, Daegu, Repubric of Korea | U37: Email: | V37: jaeseok.lee@avocarbon.com
B38: D1 | C38: Problem Solving Team
B39: Sponsor | D39: Jaeseok Lee | I39: Email | J39: jaeseok.lee@avocarbon.com | N39: Phone | O39: +82-53-610-4215 | S39: Function/Department | V39: Quality
B40: Team Leader | D40: Jonggil Jeon | I40: Email | J40: jonggil.jeon@avocarbon.com | N40: Phone | O40: +82-53-610-4225 | S40: Function/Department | V40: Production
B41: Team Member | D41: Insug Kim | I41: Email | J41: insug.kim@avocarbon.com | N41: Phone | O41: +82-53-610-4254 | S41: Function/Department | V41: Quality
B42: Team Member | D42: Changmin Park | I42: Email | J42: changmin.park@avocarbon.com | N42: Phone | O42: +82-53-610-4231 | S42: Function/Department | V42: Production
B43: Team Member | I43: Email | N43: Phone | S43: Function/Department | AC43: Specific requirement: | AI43: Actual value (nonconformity):
AC44: brush length : 14.74~15.1mm | AI44: brush length : 13.66mm (under low limit)
B45: D2 | C45: Problem Description
B46: Eckerle description:
B47: Problem description:
B48: Short brush length
...

Sheet Risk Evaluation_v1
B1: Field / 0-km complaint: Risk assessment calculation is mandatory. | Q1: Estimation regarding the additional failures from the manufactured products batch. A quantified statement of the number of failures is required. Additionally, it is recommended to determine the failure rate in ppm
Q2: (e.g. 3 parts 0-km, 11 parts Field)
B3: Calculation Sheet for Risk Evaluation | Q3: - The severity of the failure effect (e.g.: Part not mountable, noisy operation)
Q4: - The detection probability at customer side (e.g.: Detection at customer via 100% functional test or sampling inspection)
B5: INPUT | Q5: Ideally is a rating for S, O, and D like in the FMEA have to be defined. A clear qualitative statement could also be adequate. (For S e.g: Non-operating air conditioner).
C7: n: Representative sample | D7: 145000 | E7: Parts
C9: i: Number of defective products in n | D9: 1 | E9: Parts
C11: VP: Production lot between C2 and C1 | D11: 80000 | E11: Parts
C13: Confidence level (1-α) in %, per default 90% | D13: 0.9
B16: OUTPUT
C18: p=i/n: Failure rate of n | D18: =D9/D7 -> 6.8965517e-06
C20: p': Failure rate of the population Vp
C22: p'low: Lower limit of confidence interval of p'
C24: p'upp: Upper limit of confidence interval of p' | Q24: C1 : MFD as of when defective products were manufactured | Y24: Remarks:
Q25: C2 : Implementation date of the corrective actions | Y25: - In order to determine the number of defective products Internal/0-km/Field in each case separately, if necessary further limitation of VP is to be made.
C26: nC: Estimated number of delivered/manufactured defective products | Q26: Cc: MFD of complained products | Y26: - Additionally, to the expected number of failures, the failure rate should be specified in ppm nCppm=p×1.000.000
Q27: i : Number of defective products from the representative sample (Determined via sorting/testing) | Y27: - If relevant the complained lot VC is to be subtracted from nC, in order to determine the additional number of failures.
C28: nC'low: Lower limit of number of delivered/manufactured defective products | Q28: n: Representative sample | Y28: - For the determination regarding the variation of estimated nC, the confidence interval could be identified according to Appendix 1. See for this also Booklet 2 Page 55-58.
Q29: nC : Estimated number of delivered/manufactured defective products | Y29: - If i = 0 is, the confidence interval should be identified in each case, in order to represent the Worst Case.
C30: nC'upp: Upper limit of number of delivered/manufactured defective products | Q30: p=i/n: Failure rate in the representative sample | Y30: - Risk estimation for field cases:
Q31: VC : Complained lot | Y31: o In case the fundamentals for a Weibull analysis are present (Number of defective products >10 preferably with varying service life and/or mileage), this is to be performed
C32: Under the prerequisite of a binomial distribution, following calculation basis applies: | Q32: VP: Production lot between C1 and C2 | Y32: o If necessary, the determination of a representative sample can alternatively be performed as follows:
Q33: Risk evaluation: | Y33:  i: The extent of the suspected lot in the monitored market segment
C34: For i > 0 | Q34: nC = p×(VP -n) | Y34:  n: Number of complained products from the monitored market segment
C36: p'low ≤p'≤ p'upp | Q36: Fictional example of a Risk Analysis
Q37: A supplier has performed parameter modification in the welding process for the wiper system base plate on the 27.07.2010. In the worst case, the joint tube/plate cannot endure the specified mechanical stress.
C38: p'low = i/(i+(n-i+1).Ff1,f2;1-α/2) | D38: =IF(D9>0,D9/(D9+(D7-D9+1)*H38),"") -> 3.537468e-07 | F38: =IF(D9>0,D38*D92,"") -> 0 | G38: Parts | H38: =FINV(((1-D13)/2),(2*(D7-D9+1)),(2*D9)) -> 19.495722 | Q38: Affected are base plates with MFD from 27.07.2010 to 01.09.2010.
Q39: The parts from 01.08.2010 to 01.11.2010 were mounted into of 20.000 WSA, further classification is not possible.
C40: p'upp = ((i+1).Ff1,f2;1-α/2)/(n-i+(i+1).Ff1,f2;1-α/2) | D40: =IF(D9>0,(D9+1)*H40/(D7-D9+(D9+1)*H40),"") -> 3.2715885e-05 | F40: =IF(D9>0,D40*D7,"") -> 4.7438033 | G40: Parts | H40: =FINV(((1-D13)/2),(2*(D9+1)),(2*(D7-D9))) -> 2.3719629 | Q40: The customer has complained three WSA with MFD 09.08.2010, 17.10.2010 and 23.10.2010. The failure occurred in the customer plant during a sampling inspection of the vehicle. For the WSA still to be mounted until C2, the customer will 100 % perform this inspection.
Q41: It must be assumed that the critical parts, which were not detected in the customer plant, will become conspicuous as early failure in field. Since no field failures are known, no Weibull analysis is possible.
C42: nC = p⋅(VP-n) | D42: =IF(D9>0,D18*(D11-D7),"") -> -0.44827586 | E42: Parts | G42: =IF(D9>0,ROUNDUP(D42,0),"") -> -1 | H42: estimated defective products over the population | Q42: From the 20.000 WSA, 19.000 are already mounted, 1000 are still to be mounted by the customer before implementing corrective actions.
Q43: The analysis of a representative sample, taken from the still to be mounted parts resulted in the following:
C44: nC'low= p'low⋅(VP-n) | D44: =IF(D9>0,D38*(D11-D7),"") -> -0.022993542 | E44: Parts | Q44: - 450 were checked
G45: Between | H45: =IF(D9>0,ROUNDUP(D44,0),"") -> -1 | I45: and | J45: =IF(D9>0,ROUNDUP(D46,0),"") -> -3 | K45: additional failures are expected | Q45: - 2 n.O.K
C46: nC'upp= p'upp⋅(VP-n) | D46: =IF(D9>0,D40*(D11-D7),"") -> -2.1265325 | E46: Parts | Q46: Evaluation of the Risk for WSA:
Q47: Date C1 : 01.08.2010 Date C2 : 01.11.2010
C48: For i = 0 (No defective part in the sample) | Q48: VC : 3 VP: 20000
Q49: n: 450 i : 2
Q50: VP-0km: Production lot between C1 and C2 relevant for 0-km Risk
C51: Significance level (α/2) | D51: =(1-D13)/2 -> 0.05 | Q51: VP-Field: Production lot between C1 and C2 relevant for Field Risk
...

Sheet D2 - Failure Visualization
B4: Failure Visualization sheet
B8: 8D Title | L8: Complaint No.
B10: Part Number | L10: Date
L12: Version | N12: 0
C34: Specific requirement: | I34: Actual value (non conformity):

Sheet 8D Self-assessment_v1
B2: Please find further information behind cell comments.
B4: 8D self-evaluation checklist
B6: 8D Title | E6: ='8D Form_v1'!F30 -> Shrot brush length
B8: Complaint No. | E8: ='8D Form_v1'!K26 -> 0
B10: Part No. | E10: ='8D Form_v1'!R30 -> 3134320709
B12: Date | E12: 2025.06.20
B14: Version
B16: done by | E16: Jaeseok Lee
B19: Completed | F19: Requirements | G19: Comments | H19: Counts
B20: Please select:
B21: Yes | C21: N/A | D21: No | H21: cells | I21: y | J21: n/a | K21: n | L21: points | M21: score
B22: x | E22: D2 Problem Description | F22: What | G22: ='8D Form_v1'!F30 -> Shrot brush length
B23: x | F23: Where | G23: ='8D Form_v1'!F51 -> Eckerle Automotive Kft
B24: x | F24: When | G24: ='8D Form_v1'!F50 -> 2025.06.06
B25: x | F25: How many parts affected / How much | G25: ='8D Form_v1'!F52 -> 1 pcs
B26: x | F26: NOK and OK pictures available. | G26: yes
B28: x | E28: D3 Containment Actions | F28: Containment actions are clearly described and in time. | H28: 7 | I28: =COUNTA(B29:B35) -> 7 | J28: =COUNTA(C29:C35) -> 0 | K28: =COUNTA(D29:D35) -> 0 | L28: 1 | M28: =L28*H30 -> 1
B29: x
B30: x | F30: Containment actions for current production in effect | H30: =IF(I28+J28=H28,IF(K28=0,1,0),0) -> 1
B31: x | F31: Containment actions with adequate for defect mode.
B32: x | F32: Sorting results given.
B33: x | F33: Responsibility and implementation date given.
B34: x | F34: Whole supply chain covered.
B35: x | F35: All relevant customers (int./ext.) informed; if necessary authorities notified.
B37: x | E37: D4_a Root Cause Occurance | F37: TRC and MRC (Management System) systematically analyzed. (5W, Ishikawa) | H37: =IF(#REF!+#REF!=#REF!,IF(#REF!=0,1,0),0) -> #REF!
B38: x | F38: Risk assessment is available.
B40: x | E40: D4-b Root Cause Non detection | F40: TRC and MRC (Management System) systematically analyzed (5W, Ishikawa) | H40: =IF(#REF!+#REF!=#REF!,IF(#REF!=0,1,0),0) -> #REF!
B41: x | F41: MRC (leadership and/or business process) analyzed | H41: =IF(#REF!=#REF!,IF(#REF!=0,1,0),0) -> #REF!
B43: x | E43: D5/D6-a Corrective Action Occurance | F43: Defined corrective actions covering all TRC and MRC of D4_a | H43: =IF(#REF!+#REF!=#REF!,IF(#REF!=0,1,0),0) -> #REF!
B44: x | F44: Effectiveness for all corrective actions is given.
B45: x | F45: Responsibilities and implementation dates defined.
B46: x | F46: Reason for withdrawal of containment actions is documented.
B47: x | F47: Effectiveness is assessed and evaluated with regard to risks on other product /processes. A protection, e.g. thorugh Poka Yoke could be introduced. | H47: =IF(#REF!=#REF!,IF(#REF!=0,1,0),0) -> #REF!
B48: x | F48: The MRC in the business processes and/or leadership are found and corrective actions effectively introduced.
B50: x | E50: D5/D6-b Corrective Action | F50: Defined corrective actions covering all TRC and MRC of D4_a | H50: =IF(#REF!+#REF!=#REF!,IF(#REF!=0,1,0),0) -> #REF!
B51: x | F51: Effectiveness for all corrective actions is given.
B52: x | F52: Responsibilities and implementation dates defined.
B53: x | F53: Plan for monitoring effectiveness provided. Redundant tests/controls have been stopped. | H53: =IF(#REF!=#REF!,IF(#REF!=0,1,0),0) -> #REF!
B55: x | E55: D7 Preventative Actions | F55: Update of documents (FMEA, CP, PQP, directives, drawing etc.) | H55: =IF(#REF!+#REF!=#REF!,IF(#REF!=0,1,0),0) -> #REF!
B56: x | F56: Lessons learned (LL) transfer to all relevant products, processes and plants
...

Sheet D6-1_CA_Occ
E2: 근 본 대 책 실 행 (Corrective action) [D6]
B6: 문 제 점 (Problem) | F6: short brush length
B7: 공 정 명 (Process) | F7: Grinding process | L7: 검증일자 Verification date | O7: 2025.06.15
B8: 개선전-후 비교 (Comparison) | F8: 개 선 전(Before) | L8: 개 선 후(After)
B18: 내 용 (Content) | F18: Establish a standard to apply white marking on setup brushes to distinguish them from regular products and ensure clear identification. / 셋팅 브러쉬에 흰색 마킹을 적용하여 일반 제품과 구분하고 식별이 가능하도록 하기 위한 표준을 수립한다.
E23: 근 본 대 책 실 행 (Corrective action) [D6]
B27: 문 제 점 (Problem) | F27: short brush length
B28: 공 정 명 (Process) | F28: Grinding process | L28: 검증일자 Verification date | O28: 2025.06.15
B29: 개선전-후 비교 (Comparison) | F29: 개 선 전(Before) | L29: 개 선 후(After)
B39: 내 용 (Content) | F39: Establish a standard for recording and verifying the usage and collection quantities of setup parts. / 셋팅품 사용 수량과 수거 수량을 기록하고 확인할 수 있는 표준을 수립한다.
