Workbook
Name NEWNOK__: 'SQA Genba Check'!$AG$10:$AG$11
Name NEWOK__: 'SQA Genba Check'!$AG$9:$AG$10
Name Option1: List!$H$1:$H$2
Name Option2: List!$I$1:$I$2
Name Option3: List!$J$1:$J$2
Name Option4: List!$K$1:$K$2
Name Option5: List!$L$1:$L$2

Sheet Quick Response
A2: VIM Data | X2: 1
C3: Valeo Contact name [1] | I3: INCIDENT CATEGORY [3] | Q3: Which LLC was already issued on similar problem? [21]
C4: nicolas.siffrein-blanc@.com | J4: C1 | M4: CP1
J5: C1WR | M5: CP2
I6: X | J6: C2 | M6: CA
C7: PRODUCT (Designation + Ref) [2]
I8: SUPPLIER INCIDENT DETAILS
C9: Faisceau H100 DG W000065335 | I9: Valeo SRM Incident Number
I10: Date and Time of Valeo Notification | L10: Date and Time of Customer Notification
B13: WHAT IS THE PROBLEM ? > Use 5W + 2H to know what is the Current Situation ? | Q13: First findings after incident notification [22]
B14: 5W2H | I14: CHARACTERIZATION | R14: Real data ? ( please identify the involved standards ) | U14: Factor(s) to include in FTA Occ or FTA Non Det
B15: WHAT happened? [4] | C15: Standart : no naked wire Good part : no naked wire Bad part : naked wire | I15: What is the difference between good and bad parts? [11] | K15: Standart : no naked wire Good part : no naked wire Bad part : naked wire ( waiting for reception of the bad part) | Q15: 1/ ... in the MACHINE SETTINGS [23], e.g. parameters list and values, setup records
B16: WHY is it a problem? [5] | C16: risk of short circuit, risk of C1 or WR incidents | I16: Was part produced in the standard process? [12] | K16: Yes the part was produced in the standard process | Q16: 2/ ... in the OPERATIONS [24], e.g. QRAP, OK start, shift, operator, maintenance, breakdowns, cavities, tools, 5S,
B17: WHEN detected [6] | C17: 01/10/2025 | I17: When was it manufactured at Supplier? [13] | K17: 45898
Q18: 3/ ... in the QUALITY CONTROLS [25], e.g. inspection records, control means, line rejects
B19: WHO detected? [7] | C19: operator on Skawina Line | I19: Who manufactured? [14] | K19: Team leader : Khadhraoui Radhia Fial control: Wahiba Ghress matricule 328 --> Level B the level B is the level requested to control the brush card
B20: (name of operator)
B21: WHERE detected? [8] | C21: Skawina Line 18 | I21: In which other application or processes product is used? [15] | K21: V53512215, 53512445, 535 12 565, V53512525, V53512535 | Q21: 4/ ... in the RAW MATERIAL [26], e.g. component lots, suppliers, tools, cavities
B22: HOW detected? [9] | C22: visually when taking manually the motor from the box | I22: Are we capturing the defect when reinjecting product in normal process? [16] | K22: Waiting for reception of the bad part, the defect is reproduced manually by cutting the plastic isolation, the part was detected by the operator of the electrical test & the final control
Q23: 5/ ...in the PROJECT ACTIVITY [27], e.g. DV/PV records
B24: HOW MANY bad parts? [10] | C24: 1 | I24: Did a similar problem happen previously at customer or internally? [17] | K24: No
B26: BAD PART [18] | I26: GOOD PART [19] | Q26: WHAT ARE THE IMMEDIATE COUNTERMEASURES (24 hours)?
Q29: 1. IMMEDIATE COUNTERMEASURES IN SUPPLIER PERIMETER ? [31] | S29: WHO | U29: DATE | V29: WHERE
Q31: Display the quality alert in production line | S31: Sana Dkhil | U31: 01/10/2025 | V31: MNG2 production line
Q33: Check the quantity in stock in AVO, Transit, VALEO sites for all similar part numbers | S33: Nihed Nabli | U33: 02/10/2025
K36: Origin of the part | L36: Production
B40: SORTING ACTIVITY to protect customer [20]
D43: Nb. NG Parts | F43: Nb. Sorted | H43: PPM | J43: Sorting date | K43: WHO | M43: Identification OK parts | Q43: 2. IMMEDIATE COUNTERMEASURES IN VALEO LINE ? [32] | S43: WHO | U43: DATE | V43: WHERE
B44: -Results of sorting in Valeo's Customer plant | G44: = | H44: =IF(F44=0,"'----'",D44/F44*1000000) -> '----' | I44: PPM
B45: -Results of sorting in Valeo Plant | G45: = | H45: =IF(F45=0,"'----'",D45/F45*1000000) -> '----' | I45: PPM
B46: -Results of sorting in Other Valeo Plants | H46: =IF(F46=0,"'----'",D46/F46*1000000) -> '----' | I46: PPM
B47: -Results of sorting in Transport | G47: = | H47: =IF(F47=0,"'----'",D47/F47*1000000) -> '----' | I47: PPM
B48: -Results of sorting in Valeo's Logistics platform | F48: =2040+510 -> 2550 | H48: =IF(F48=0,"'----'",D48/F48*1000000) -> 0 | I48: PPM
B49: -Results of sorting in Supplier's Logistics platform | G49: = | H49: =IF(F49=0,"'----'",D49/F49*1000000) -> '----' | I49: PPM
B50: -Results of sorting in Supplier plant | F50: =23*85 -> 1955 | H50: =IF(F50=0,"'----'",D50/F50*1000000) -> 0 | I50: PPM | J50: Baraa B | K50: 45932
B51: -Results of sorting in after-sales stocks | G51: = | H51: =IF(F51=0,"'----'",D51/F51*1000000) -> '----' | I51: PPM
B52: TOTAL SORTING | D52: =SUM(D44:D51) -> 0 | F52: =SUM(E44:F51) -> 4505 | G52: = | H52: =IF(F52=0,"'----'",D52/F52*1000000) -> 0 | I52: PPM
B54: Production dates of sorted parts | C54: From | D54: To | J54: First certified good shipment: | L54: Label's Number | N54: Date
C55: 45898 | D55: 45932 | L55: 202510021 | N55: 45932
B56: Period of NG parts | C56: Earliest NG part Date | D56: Latest NG part Date | L56: Identification OK parts / OK pallets
...

Sheet Logical Thinking grid
A1: Logical Thinking Assessment grid
A2: Rules
A3: 1) During QRQC Meeting - Assign a person who will fulfill Logical thiking assessment grid - Assessment can be fulfilled in PDCA-FTA template - Review PDCA-FTA step by step (QR, FTA Occurrence & Non detection & 5 WHYs, ....) and write all comments done to improve content of PDCA-FTA - During next review , logical thinking grid might be used to check if all improvements requested have been done Logical thinking is the history of OJT done. This will allow to not re-challenge from beginning the PDCA-FTA and focus only on step not validated yet 2) Application at meeting room (Formal PDCA presentation) - 15' PDCA presentation using SRM : PDCA-FTA Owner - PDCA Synthesis to be completed with your logical thinking assessment during 10' : Fulfill Logical thinking assessment grid : Auditor - Share your assessment with on the job training, welcome the new problems and respect others | J3: Which step has been validated? | K3: Date of Validation
J4: QR & Sorting Timeline Process Flow
J5: FTA Occurrence & 5 Why's
J6: FTA Non Detection & 5 Why's
J7: Action Plan & Gemba review
A8: 3) Questions formulation Thank you for the presentation. I particularly liked………… (precise element of the workshop, cause…) I have a question regarding....... => Can you show me evidence and data regarding ........? => This will help me to understand ...........
A9: PDCA synthesis
A10: QR - Sorting - Timeline - Process Flow
A11: QR | J11: 1. 5W2H & Characterization of issue clear?
A15: Sorting | J15: 1. Is sorting criteria clear ? 2. Customer secured ? 3. Have you identified the time and place when/where the incident occurred?
A19: Timeline | J19: 1. Key events hilighted on the timeline ? 2. Key events identified as factors in the FTA's ?
A23: Process Flow | J23: 1. Is flow- chart available & reflectsreal situation when issue occurred ? (flow-Chart, photograph, manual sketch,.... )
A27: FTA OCCURRENCE & 5 Why's
A28: FTA Occurrence | J28: 1. Is occurrence root cause identified ?
A32: 5 Why's | J32: 1. Are system and management root causes identified?
A36: FTA NON DETECTION & 5 Why's
A37: FTA Non DETECTION | J37: 1. Is non detection root cause identified ?
A41: 5 Why's | J41: 1. Are system and management root causes identified?
A45: ACTION PLAN & GEMBA REVIEW
A46: ACTION PLAN | J46: 1. Is defect reproduced? 2. Are technical & systemic actions defined? 3. Are LLCs created both occurrence and non-detection when relevant ?
A50: GEMBA REVIEW | J50: 1. Have Workinstructions / Standards been updated? 2. Are operators aware of the corrective actions and know explain them ? 3. Do Process match with expected corrective actions? 4. Has solution been properly validated & is solution effective?

Sheet Assign
A1: ASSIGNMENT / BREAKDOWN
A2: N° | B2: ASSIGNMENT [1] | C2: RESULTS [2] | D2: WHO [3] | E2: Due date [4] | F2: Done date [5]
A3: 1 | B3: Organize the pickup of the bad part by DHL | D3: Lassaad Charaabi | E3: 45932
A4: 2 | B4: Check the traceability ( SCRAP, QRAP, maintenace intervention) | C4: no special events (0 scrap & 0 maintenace intervention) | D4: Lassaad Charaabi | E4: 45932 | F4: 45932
A5: 3 | B5: Reinject the similar defect | C5: The similar defect is detected by the final control & the operator of the mounting connector | D5: Zohra Souissi | E5: 45932 | F5: 45932
A6: 4
A7: 5
A8: 6
A9: 7
A10: 8
A11: 9
A12: 10
A13: 11
A14: 12
A15: 13
A16: 14
A17: 15
... A32: 30

Sheet Timeline
A1: TIMELINE [1]
A5: Week / Date
A6: Qty produced
A7: Qty NOK detected [2]
A8: Defect rate (ppm)* | B8: =IFERROR(B7/B6*1000000,"") | C8: =IFERROR(C7/C6*1000000,"") | D8: =IFERROR(D7/D6*1000000,"") | E8: =IFERROR(E7/E6*1000000,"") | F8: =IFERROR(F7/F6*1000000,"") | G8: =IFERROR(G7/G6*1000000,"") | H8: =IFERROR(H7/H6*1000000,"") | I8: =IFERROR(I7/I6*1000000,"") | ... AB8: =IFERROR(AB7/AB6*1000000,"")
A9: * If you have ppm chart available, it can be pasted below
B14: Report date and events which may have generated the occurrence or lack of detection. | F14: Report date and events which may have generated the occurrence or lack of detection. | J14: Report date and events which may have generated the occurrence or lack of detection. | N14: Report date of notification of the First Defect detected @ Valeo / Customer | R14: Report date and Immediate Countermeasure | V14: Report date and Immediate Countermeasure | Z14: Report date and Final Countermeasure after Check Act
A17: DEFECT RATE (PPM)

Sheet Process Flow
A1: PROCESS FLOW [1]

Sheet FTA Occ & 5 Whys
A1: FACTOR TREE ANALYSIS FOR OCCURRENCE - Why the problem occurred ?
A3: PROBLEM DESCRIPTION (Supplier view) [1] | C3: =IF('Quick Response'!K15="","",'Quick Response'!K15) -> Standart : no naked wire Good part : no naked wire Bad part : naked wire ( waiting for reception of the bad part)
A5: 4M [2] | B5: FACTORS [3] | C5: STANDARD [5] | E5: Factor VALUE on OK PARTS [6] | F5: Factor VALUE on BAD PARTS [7] | G5: JUDGMENT | K5: Potential Root Causes | L5: 1) Ask WHY until you arrive at the real root cause. 2) For each WHY level, decide if a countermeasure (corrective or preventive action) is to be defined and put a 'Y'.
E6: Good Part / Situation taken as reference [8] ............................. | F6: Bad Part / Situation taken as reference [9] ............................. | G6: Std OK [10] | H6: Meet std [11] | I6: Direct link [12] | L6: 5 WHYs | N6: Countermeasure?
C7: What was the standard value and tolerance? | L7: 1st WHY
C8: Where was the standard value defined (name, number and index of the document) ? | L8: 2nd WHY
L9: 3rd WHY
C10: How was the standard value measured or verified? | L10: 4th WHY
C11: What was the frequency of measurement or verification? | L11: 5th WHY
C12: What was the standard value and tolerance? | L12: 1st WHY
C13: Where was the standard value defined (name, number and index of the document) ? | L13: 2nd WHY
L14: 3rd WHY
C15: How was the standard value measured or verified? | L15: 4th WHY
C16: What was the frequency of measurement or verification? | L16: 5th WHY
C17: What was the standard value and tolerance? | L17: 1st WHY
C18: Where was the standard value defined (name, number and index of the document) ? | L18: 2nd WHY
L19: 3rd WHY
C20: How was the standard value measured or verified? | L20: 4th WHY
C21: What was the frequency of measurement or verification? | L21: 5th WHY
C22: What was the standard value and tolerance? | L22: 1st WHY
C23: Where was the standard value defined (name, number and index of the document) ? | L23: 2nd WHY
L24: 3rd WHY
C25: How was the standard value measured or verified? | L25: 4th WHY
C26: What was the frequency of measurement or verification? | L26: 5th WHY
C27: What was the standard value and tolerance? | L27: 1st WHY
C28: Where was the standard value defined (name, number and index of the document) ? | L28: 2nd WHY
L29: 3rd WHY
C30: How was the standard value measured or verified? | L30: 4th WHY
C31: What was the frequency of measurement or verification? | L31: 5th WHY
C32: What was the standard value and tolerance? | L32: 1st WHY
C33: Where was the standard value defined (name, number and index of the document) ? | L33: 2nd WHY
L34: 3rd WHY
C35: How was the standard value measured or verified? | L35: 4th WHY
C36: What was the frequency of measurement or verification? | L36: 5th WHY

Sheet FTA Non Det & 5 Whys
A1: FACTOR TREE ANALYSIS FOR NON DETECTION - Why the problem was not detected ? [14]
A3: PROBLEM DESCRIPTION (Supplier view) [1] | C3: =IF('Quick Response'!K15="","",'Quick Response'!K15) -> Standart : no naked wire Good part : no naked wire Bad part : naked wire ( waiting for reception of the bad part)
A5: 4M [2] | B5: FACTORS [3] | C5: STANDARD [5] | E5: Factor VALUE on OK PARTS [6] | F5: Factor VALUE on BAD PARTS [7] | G5: JUDGMENT | K5: Potential Root Causes | L5: 1) Ask WHY until you arrive at the real root cause. 2) For each WHY level, decide if a countermeasure (corrective or preventive action) is to be defined and put a 'Y'.
E6: Good Part / Situation taken as reference [8] ............................. | F6: Bad Part / Situation taken as reference [9] ............................. | G6: Std OK [10] | H6: Meet std [11] | I6: Direct link [12] | L6: 5 WHYs | N6: Countermeasure?
C7: What was the standard value and tolerance? | L7: 1st WHY
C8: Where was the standard value defined (name, number and index of the document) ? | L8: 2nd WHY
L9: 3rd WHY
C10: How was the standard value measured or verified? | L10: 4th WHY
C11: What was the frequency of measurement or verification? | L11: 5th WHY
C12: What was the standard value and tolerance? | L12: 1st WHY
C13: Where was the standard value defined (name, number and index of the document) ? | L13: 2nd WHY
L14: 3rd WHY
C15: How was the standard value measured or verified? | L15: 4th WHY
C16: What was the frequency of measurement or verification? | L16: 5th WHY
C17: What was the standard value and tolerance? | L17: 1st WHY
C18: Where was the standard value defined (name, number and index of the document) ? | L18: 2nd WHY
L19: 3rd WHY
C20: How was the standard value measured or verified? | L20: 4th WHY
C21: What was the frequency of measurement or verification? | L21: 5th WHY
C22: What was the standard value and tolerance? | L22: 1st WHY
C23: Where was the standard value defined (name, number and index of the document) ? | L23: 2nd WHY
L24: 3rd WHY
C25: How was the standard value measured or verified? | L25: 4th WHY
C26: What was the frequency of measurement or verification? | L26: 5th WHY
C27: What was the standard value and tolerance? | L27: 1st WHY
C28: Where was the standard value defined (name, number and index of the document) ? | L28: 2nd WHY
L29: 3rd WHY
C30: How was the standard value measured or verified? | L30: 4th WHY
C31: What was the frequency of measurement or verification? | L31: 5th WHY
C32: What was the standard value and tolerance? | L32: 1st WHY
C33: Where was the standard value defined (name, number and index of the document) ? | L33: 2nd WHY
L34: 3rd WHY
C35: How was the standard value measured or verified? | L35: 4th WHY
C36: What was the frequency of measurement or verification? | L36: 5th WHY

Sheet Action plan & Genba review
A1: ANALYSIS PDCA
A3: REPRODUCE THE DEFECT
A4: WHAT WAS DONE TO REPRODUCE THE CONCERN? [1]
A5: HOW WAS IT DONE? [2]
A6: WHEN WAS IT DONE? [3]
A7: WHAT WAS THE RESULT? [4]
A9: ACTION PLAN FOR PERMANENT COUNTERMEASURES - OCCURRENCE | I9: CHECK | M9: ACT | S9: List Root Cause OCC
A10: ROOT-CAUSE [5] select the Root Cause among the list proposed | B10: TYPE OF COUNTERMEASURE [6] | C10: COUNTERMEASURE [7] | D10: STANDARD NUMBER REVISION LEVEL [8] | E10: WHO [9] | F10: Due date [10] | G10: Done date [11] | I10: Are ALL users including their Direct Manager trained to use this STANDARD? [12] | J10: Is there an ENFORCEMENT plan for the Direct manager to ensure the respect of this STANDARD? [13] | K10: Genba Check Done and OK (Date) [14] | M10: Document updated? | P10: Date when all relevant FMEAs and Control Plans were updated [18] | Q10: Generalization to other lines / products / site(s) [19] | R10: LLC Done? YES /NO [20] | S10: {=IFERROR(INDEX('FTA Occ & 5 Whys'!M7, MATCH("YES", 'FTA Occ & 5 Whys'!N7, 0)),"")}
M11: Design FMEA [15] | N11: Process FMEA [16] | O11: Control Plan [17] | S11: {=IFERROR(INDEX('FTA Occ & 5 Whys'!M8, MATCH("YES", 'FTA Occ & 5 Whys'!N8, 0)),"")}
S13: {=IFERROR(INDEX('FTA Occ & 5 Whys'!M10, MATCH("YES", 'FTA Occ & 5 Whys'!N10, 0)),"")}
S14: {=IFERROR(INDEX('FTA Occ & 5 Whys'!M11, MATCH("YES", 'FTA Occ & 5 Whys'!N11, 0)),"")}
S15: {=IFERROR(INDEX('FTA Occ & 5 Whys'!M12, MATCH("YES", 'FTA Occ & 5 Whys'!N12, 0)),"")}
S16: {=IFERROR(INDEX('FTA Occ & 5 Whys'!M13, MATCH("YES", 'FTA Occ & 5 Whys'!N13, 0)),"")}
S17: {=IFERROR(INDEX('FTA Occ & 5 Whys'!M14, MATCH("YES", 'FTA Occ & 5 Whys'!N14, 0)),"")}
S18: {=IFERROR(INDEX('FTA Occ & 5 Whys'!M15, MATCH("YES", 'FTA Occ & 5 Whys'!N15, 0)),"")}
S19: {=IFERROR(INDEX('FTA Occ & 5 Whys'!M16, MATCH("YES", 'FTA Occ & 5 Whys'!N16, 0)),"")}
S20: {=IFERROR(INDEX('FTA Occ & 5 Whys'!M17, MATCH("YES", 'FTA Occ & 5 Whys'!N17, 0)),"")}
S21: {=IFERROR(INDEX('FTA Occ & 5 Whys'!M18, MATCH("YES", 'FTA Occ & 5 Whys'!N18, 0)),"")}
S22: {=IFERROR(INDEX('FTA Occ & 5 Whys'!M19, MATCH("YES", 'FTA Occ & 5 Whys'!N19, 0)),"")}
S23: {=IFERROR(INDEX('FTA Occ & 5 Whys'!M20, MATCH("YES", 'FTA Occ & 5 Whys'!N20, 0)),"")}
S24: {=IFERROR(INDEX('FTA Occ & 5 Whys'!M21, MATCH("YES", 'FTA Occ & 5 Whys'!N21, 0)),"")}
A28: ACTION PLAN FOR PERMANENT COUNTERMEASURES - NON DETECTION | I28: CHECK | M28: ACT | S28: List Root Cause NON DET
A29: ROOT-CAUSE [5] select the Root Cause among the list proposed | B29: TYPE OF COUNTERMEASURE [6] | C29: COUNTERMEASURE [7] | D29: STANDARD NUMBER REVISION LEVEL [8] | E29: WHO [9] | F29: Due date [10] | G29: Done date [11] | I29: Are ALL users including their Direct Manager trained to use this STANDARD? [12] | J29: Is there an ENFORCEMENT plan for the Direct manager to ensure the respect of this STANDARD? [13] | K29: Genba Check Done and OK (Date) [14] | M29: Document updated? | P29: Date when all relevant FMEAs and Control Plans were updated [18] | Q29: Generalization to other lines / products / site(s) [19] | R29: LLC Done? YES /NO [20] | S29: {=IFERROR(INDEX('FTA Non Det & 5 Whys'!M7, MATCH("YES", 'FTA Non Det & 5 Whys'!N7, 0)),"")}
M30: Design FMEA [15] | N30: Process FMEA [16] | O30: Control Plan [17] | S30: {=IFERROR(INDEX('FTA Non Det & 5 Whys'!M8, MATCH("YES", 'FTA Non Det & 5 Whys'!N8, 0)),"")}
S31: {=IFERROR(INDEX('FTA Non Det & 5 Whys'!M9, MATCH("YES", 'FTA Non Det & 5 Whys'!N9, 0)),"")}
S32: {=IFERROR(INDEX('FTA Non Det & 5 Whys'!M10, MATCH("YES", 'FTA Non Det & 5 Whys'!N10, 0)),"")}
S33: {=IFERROR(INDEX('FTA Non Det & 5 Whys'!M11, MATCH("YES", 'FTA Non Det & 5 Whys'!N11, 0)),"")}
S34: {=IFERROR(INDEX('FTA Non Det & 5 Whys'!M12, MATCH("YES", 'FTA Non Det & 5 Whys'!N12, 0)),"")}
S35: {=IFERROR(INDEX('FTA Non Det & 5 Whys'!M13, MATCH("YES", 'FTA Non Det & 5 Whys'!N13, 0)),"")}
S36: {=IFERROR(INDEX('FTA Non Det & 5 Whys'!M14, MATCH("YES", 'FTA Non Det & 5 Whys'!N14, 0)),"")}
S37: {=IFERROR(INDEX('FTA Non Det & 5 Whys'!M15, MATCH("YES", 'FTA Non Det & 5 Whys'!N15, 0)),"")}
S38: {=IFERROR(INDEX('FTA Non Det & 5 Whys'!M16, MATCH("YES", 'FTA Non Det & 5 Whys'!N16, 0)),"")}
S39: {=IFERROR(INDEX('FTA Non Det & 5 Whys'!M17, MATCH("YES", 'FTA Non Det & 5 Whys'!N17, 0)),"")}
S40: {=IFERROR(INDEX('FTA Non Det & 5 Whys'!M18, MATCH("YES", 'FTA Non Det & 5 Whys'!N18, 0)),"")}
S41: {=IFERROR(INDEX('FTA Non Det & 5 Whys'!M19, MATCH("YES", 'FTA Non Det & 5 Whys'!N19, 0)),"")}
S42: {=IFERROR(INDEX('FTA Non Det & 5 Whys'!M20, MATCH("YES", 'FTA Non Det & 5 Whys'!N20, 0)),"")}
S43: {=IFERROR(INDEX('FTA Non Det & 5 Whys'!M21, MATCH("YES", 'FTA Non Det & 5 Whys'!N21, 0)),"")}

Sheet SQA Genba Check
C1: Genba Check StEDE PDCA Genba Check Efficiency control - StEDE3 workstation assesment
B3: Supplier Name | E3: StEDE PDCA Genba Check | N3: EFFICIENCY CONTROL | S3: StEDE3 Workstation assesment result
B4: Supplier Location
B5: Audit date
B6: Auditor name | N6: Number of parts since actions are in place
B7: Incident number | C7: Root cause | D7: Nb | E7: Action: TECHNICAL / SYSTEMIC CORRECTIVE ACTION | F7: Existence: STANDARD NUMBER REVISION LEVEL | G7: Deployment: Are ALL users including their N+1 (Direct Manager) trained to use this STANDARD ? Yes / No | H7: Enforcement: Is there an ENFORCEMENT plan for the N+1 ( Direct manager ) to ensure the respect of this STANDARD ? Yes / No | I7: Action | J7: Existence | K7: Deployment | L7: Enforcement | N7: Produced | P7: Bad parts | S7: StEDE 3 Workstation assesment result
A8: TECHNICAL / SYSTEMIC CORRECTIVE ACTION - OCCURRENCE | B8: =IF('Quick Response'!L9="","",'Quick Response'!L9) | C8: =IF('Action plan & Genba review'!A12="","",'Action plan & Genba review'!A12) | D8: 1 | E8: =IF('Action plan & Genba review'!C12="","",'Action plan & Genba review'!C12) | F8: =IF('Action plan & Genba review'!D12="","",'Action plan & Genba review'!D12) | G8: =IF('Action plan & Genba review'!I12="","",'Action plan & Genba review'!I12) | H8: =IF('Action plan & Genba review'!J12="","",'Action plan & Genba review'!J12)
B9: Confirmed on Genba: Supplier / Valeo SQA: Y/N
B10: =IF('Quick Response'!L9="","",'Quick Response'!L9) | C10: =IF('Action plan & Genba review'!A13="","",'Action plan & Genba review'!A13) | D10: 2 | E10: =IF('Action plan & Genba review'!C13="","",'Action plan & Genba review'!C13) | F10: =IF('Action plan & Genba review'!D13="","",'Action plan & Genba review'!D13) | G10: =IF('Action plan & Genba review'!I13="","",'Action plan & Genba review'!I13) | H10: =IF('Action plan & Genba review'!J13="","",'Action plan & Genba review'!J13)
B11: Confirmed on Genba: Supplier / Valeo SQA: Y/N
B12: =IF('Quick Response'!L9="","",'Quick Response'!L9) | C12: =IF('Action plan & Genba review'!A14="","",'Action plan & Genba review'!A14) | D12: 3 | E12: =IF('Action plan & Genba review'!C14="","",'Action plan & Genba review'!C14) | F12: =IF('Action plan & Genba review'!D14="","",'Action plan & Genba review'!D14) | G12: =IF('Action plan & Genba review'!I14="","",'Action plan & Genba review'!I14) | H12: =IF('Action plan & Genba review'!J14="","",'Action plan & Genba review'!J14)
B13: Confirmed on Genba: Supplier / Valeo SQA: Y/N
B14: =IF('Quick Response'!L9="","",'Quick Response'!L9) | C14: =IF('Action plan & Genba review'!A15="","",'Action plan & Genba review'!A15) | D14: 4 | E14: =IF('Action plan & Genba review'!C15="","",'Action plan & Genba review'!C15) | F14: =IF('Action plan & Genba review'!D15="","",'Action plan & Genba review'!D15) | G14: =IF('Action plan & Genba review'!I15="","",'Action plan & Genba review'!I15) | H14: =IF('Action plan & Genba review'!J15="","",'Action plan & Genba review'!J15)
B15: Confirmed on Genba: Supplier / Valeo SQA: Y/N
B16: =IF('Quick Response'!L9="","",'Quick Response'!L9) | C16: =IF('Action plan & Genba review'!A16="","",'Action plan & Genba review'!A16) | D16: 5 | E16: =IF('Action plan & Genba review'!C16="","",'Action plan & Genba review'!C16) | F16: =IF('Action plan & Genba review'!D16="","",'Action plan & Genba review'!D16) | G16: =IF('Action plan & Genba review'!I16="","",'Action plan & Genba review'!I16) | H16: =IF('Action plan & Genba review'!J16="","",'Action plan & Genba review'!J16)
B17: Confirmed on Genba: Supplier / Valeo SQA: Y/N
B18: =IF('Quick Response'!L9="","",'Quick Response'!L9) | C18: =IF('Action plan & Genba review'!A17="","",'Action plan & Genba review'!A17) | D18: 6 | E18: =IF('Action plan & Genba review'!C17="","",'Action plan & Genba review'!C17) | F18: =IF('Action plan & Genba review'!D17="","",'Action plan & Genba review'!D17) | G18: =IF('Action plan & Genba review'!I17="","",'Action plan & Genba review'!I17) | H18: =IF('Action plan & Genba review'!J17="","",'Action plan & Genba review'!J17)
B19: Confirmed on Genba: Supplier / Valeo SQA: Y/N
B20: =IF('Quick Response'!L9="","",'Quick Response'!L9) | C20: =IF('Action plan & Genba review'!A18="","",'Action plan & Genba review'!A18) | D20: 7 | E20: =IF('Action plan & Genba review'!C18="","",'Action plan & Genba review'!C18) | F20: =IF('Action plan & Genba review'!D18="","",'Action plan & Genba review'!D18) | G20: =IF('Action plan & Genba review'!I18="","",'Action plan & Genba review'!I18) | H20: =IF('Action plan & Genba review'!J18="","",'Action plan & Genba review'!J18)
B21: Confirmed on Genba: Supplier / Valeo SQA: Y/N
B22: =IF('Quick Response'!L9="","",'Quick Response'!L9) | C22: =IF('Action plan & Genba review'!A19="","",'Action plan & Genba review'!A19) | D22: 8 | E22: =IF('Action plan & Genba review'!C19="","",'Action plan & Genba review'!C19) | F22: =IF('Action plan & Genba review'!D19="","",'Action plan & Genba review'!D19) | G22: =IF('Action plan & Genba review'!I19="","",'Action plan & Genba review'!I19) | H22: =IF('Action plan & Genba review'!J19="","",'Action plan & Genba review'!J19)
B23: Confirmed on Genba: Supplier / Valeo SQA: Y/N
B24: =IF('Quick Response'!L9="","",'Quick Response'!L9) | C24: =IF('Action plan & Genba review'!A20="","",'Action plan & Genba review'!A20) | D24: 9 | E24: =IF('Action plan & Genba review'!C20="","",'Action plan & Genba review'!C20) | F24: =IF('Action plan & Genba review'!D20="","",'Action plan & Genba review'!D20) | G24: =IF('Action plan & Genba review'!I20="","",'Action plan & Genba review'!I20) | H24: =IF('Action plan & Genba review'!J20="","",'Action plan & Genba review'!J20)
B25: Confirmed on Genba: Supplier / Valeo SQA: Y/N
B26: =IF('Quick Response'!L9="","",'Quick Response'!L9) | C26: =IF('Action plan & Genba review'!A21="","",'Action plan & Genba review'!A21) | D26: 10 | E26: =IF('Action plan & Genba review'!C21="","",'Action plan & Genba review'!C21) | F26: =IF('Action plan & Genba review'!D21="","",'Action plan & Genba review'!D21) | G26: =IF('Action plan & Genba review'!I21="","",'Action plan & Genba review'!I21) | H26: =IF('Action plan & Genba review'!J21="","",'Action plan & Genba review'!J21)
B27: Confirmed on Genba: Supplier / Valeo SQA: Y/N
A29: TECHNICAL / SYSTEMIC CORRECTIVE ACTION - NON DETECTION | B29: =IF('Quick Response'!L9="","",'Quick Response'!L9) | C29: =IF('Action plan & Genba review'!A31="","",'Action plan & Genba review'!A31) | D29: 11 | E29: =IF('Action plan & Genba review'!C31="","",'Action plan & Genba review'!C31) | F29: =IF('Action plan & Genba review'!D31="","",'Action plan & Genba review'!D31) | G29: =IF('Action plan & Genba review'!I31="","",'Action plan & Genba review'!I31) | H29: =IF('Action plan & Genba review'!J31="","",'Action plan & Genba review'!J31)
B30: Confirmed on Genba: Supplier / Valeo SQA: Y/N | AF30: ok | AG30: ok
B31: =IF('Quick Response'!L9="","",'Quick Response'!L9) | C31: =IF('Action plan & Genba review'!A32="","",'Action plan & Genba review'!A32) | D31: 12 | E31: =IF('Action plan & Genba review'!C32="","",'Action plan & Genba review'!C32) | F31: =IF('Action plan & Genba review'!D32="","",'Action plan & Genba review'!D32) | G31: =IF('Action plan & Genba review'!I32="","",'Action plan & Genba review'!I32) | H31: =IF('Action plan & Genba review'!J32="","",'Action plan & Genba review'!J32) | AF31: nok | AG31: nok
B32: Confirmed on Genba: Supplier / Valeo SQA: Y/N | AF32: conditional ok | AG32: conditional ok
B33: =IF('Quick Response'!L9="","",'Quick Response'!L9) | C33: =IF('Action plan & Genba review'!A33="","",'Action plan & Genba review'!A33) | D33: 13 | E33: =IF('Action plan & Genba review'!C33="","",'Action plan & Genba review'!C33) | F33: =IF('Action plan & Genba review'!D33="","",'Action plan & Genba review'!D33) | G33: =IF('Action plan & Genba review'!I33="","",'Action plan & Genba review'!I33) | H33: =IF('Action plan & Genba review'!J33="","",'Action plan & Genba review'!J33)
B34: Confirmed on Genba: Supplier / Valeo SQA: Y/N
B35: =IF('Quick Response'!L9="","",'Quick Response'!L9) | C35: =IF('Action plan & Genba review'!A34="","",'Action plan & Genba review'!A34) | D35: 14 | E35: =IF('Action plan & Genba review'!C34="","",'Action plan & Genba review'!C34) | F35: =IF('Action plan & Genba review'!D34="","",'Action plan & Genba review'!D34) | G35: =IF('Action plan & Genba review'!I34="","",'Action plan & Genba review'!I34) | H35: =IF('Action plan & Genba review'!J34="","",'Action plan & Genba review'!J34)
B36: Confirmed on Genba: Supplier / Valeo SQA: Y/N
B37: =IF('Quick Response'!L9="","",'Quick Response'!L9) | C37: =IF('Action plan & Genba review'!A35="","",'Action plan & Genba review'!A35) | D37: 15 | E37: =IF('Action plan & Genba review'!C35="","",'Action plan & Genba review'!C35) | F37: =IF('Action plan & Genba review'!D35="","",'Action plan & Genba review'!D35) | G37: =IF('Action plan & Genba review'!I35="","",'Action plan & Genba review'!I35) | H37: =IF('Action plan & Genba review'!J35="","",'Action plan & Genba review'!J35)
B38: Confirmed on Genba: Supplier / Valeo SQA: Y/N
B39: =IF('Quick Response'!L9="","",'Quick Response'!L9) | C39: =IF('Action plan & Genba review'!A36="","",'Action plan & Genba review'!A36) | D39: 16 | E39: =IF('Action plan & Genba review'!C36="","",'Action plan & Genba review'!C36) | F39: =IF('Action plan & Genba review'!D36="","",'Action plan & Genba review'!D36) | G39: =IF('Action plan & Genba review'!I36="","",'Action plan & Genba review'!I36) | H39: =IF('Action plan & Genba review'!J36="","",'Action plan & Genba review'!J36)
B40: Confirmed on Genba: Supplier / Valeo SQA: Y/N
B41: =IF('Quick Response'!L9="","",'Quick Response'!L9) | C41: =IF('Action plan & Genba review'!A37="","",'Action plan & Genba review'!A37) | D41: 17 | E41: =IF('Action plan & Genba review'!C37="","",'Action plan & Genba review'!C37) | F41: =IF('Action plan & Genba review'!D37="","",'Action plan & Genba review'!D37) | G41: =IF('Action plan & Genba review'!I37="","",'Action plan & Genba review'!I37) | H41: =IF('Action plan & Genba review'!J37="","",'Action plan & Genba review'!J37)
B42: Confirmed on Genba: Supplier / Valeo SQA: Y/N
...

Sheet StEDE3 Matrix
B2: StEDE3 Workstation Assessment v2.5
I3: =COUNTIF(I15:K17,"ok") -> 0
A5: Supplier : | B5: =IF('SQA Genba Check'!C3="","",'SQA Genba Check'!C3)
A6: Plant location :
A7: Assessment date : | E7: StEDE3 ASSESSMENT RESULT : | I7: =COUNTIF(I15:K17,"ok")&"/ 9" -> 0/ 9
A8: Workstation assessed :
A9: Assessor / Company
A10: Setter :
A11: Operator : | I11: For supplier self assesment activity, column to be assessed by:
A12: Step 1 : 360° Variability Hunting | E12: Step 2 : StEDE3 Matrix | I12: Direct Manager of the user | K12: Manager from an other APU/Department
A13: Silent Workstation observation for 10/15 min, to detect any potential Variability related to : - machine settings - operator activities - quality controls | E13: StEDE3 Matrix Excellence Through Standards | I13: EXISTING ? | J13: DEPLOYED ? How were the users trained to apply this STANDARD ? ( including their Direct Manager if not the trainer ) | K13: ENFORCED ? What is the Direct Manager of the users doing to ensure the strict and continuous EXECUTION of this STANDARD ?
I14: Clear, Visible, Quantified, Doable. | J14: Respected by users. Can be explained by users. | K14: The Direct Manager checks on genba the respect of the standards and in case a gap is found an action is defined
E15: For a given Process / Workstation : Are StANDARDS for… | F15: … Set-up Parameters … | H15: Parameters list, values and limits and necessary work instructions to set the machine/workstation up for production of the selected part number (to be compared with those used during the FDPR / IS)
F16: ... Work Instructions … | H16: Instructions defining how to operate the station safely, to produce parts, and how to maintain the equipment.
F17: … Quality Controls … | H17: Activities to control the quality of the operation or of the product after transformation to ensure only good parts are transferred to the next station
B21: Conclusion :
A30: Step 3 : Findings
A31: StEDE3 Matrix Excellence Through Standards | D31: EXISTING ? | E31: DEPLOYED ? | F31: ENFORCED ? | H31: "Reduction of the variability in our processes, being production or administrative, is key to ensure the sustainability of any continuous improvement"
A32: =COUNTIF(I15:K17,"ok")&" / 9" -> 0 / 9 | D32: Clear, Visible, Quantified, Doable. | E32: Respected by users. Can be explained by users. | F32: Audited by direct manager on Genba at a frequency defined based on frequency of usage of standard. | G32: Category (Ex / Dep / Enf) | H32: Findings and next steps | K32: Owner | L32: Date | M32: Status | N32: Is FMEA update required ? Yes / No | O32: If "Yes", done date
A33: For a given Process / Workstation : Are StANDARDS for… | B33: ...Set-up Parameters … | D33: =I15 -> 0 | E33: =K15 -> 0 | F33: =#REF! -> #REF! | H33: Finding #1 : Next step :
H35: Finding #2 : Next step :
H37: Finding #3 : Next step :
B39: ... Work Instructions … | D39: =I16 -> 0 | E39: =J16 -> 0 | F39: =K16 -> 0 | H39: Finding #1 : Next step :
H41: Finding #2 : Next step :
H43: Finding #3 : Next step :
B45: ...Quality Controls … | D45: =I17 -> 0 | E45: =J17 -> 0 | F45: =K17 -> 0 | H45: Finding #1 : Next step :
H47: Finding #2 : Next step :
H49: Finding #3 : Next step :
B52: VALEO signature | I52: SUPPLIER signature

Sheet List
A1: OK | B1: NOK | C1: NOK | H1: OK | I1: OK | J1: NOK
A2: NOK | B2: Conditional OK | C2: Conditional OK | H2: NOK | I2: NOK | J2: Conditional OK

Sheet Revision
A2: Level | B2: What | C2: Who | D2: When
A3: Rev 1 | B3: First release of Template including StEDE requirements for the formalization of Action Plan | C3: D. Dimur / D. Masucci | D3: 42398
A4: Rev 2 | B4: In StEDE action plan, the header "WHO" changed to "WHO and JOB POSITION" | C4: D. Masucci | D4: 42453
A5: Rev 3 | B5: Tab sheet "Timeline and Process Flow" and "Logical Thinking Grid" grid added. Rephrasing of wording in FTA | C5: D. Masucci | D5: 42618
A6: Rev 4 | B6: StEDE ACTION PLAN FOR SYSTEMIC CORRECTIVE ACTION, Genba Check and StEDE3 added. Comments in red corner replaced to be displayed when the cursor is in the cell | C6: D. Dimur / D. Masucci | D6: 42780
A7: Rev 4.1 [A05] | B7: Correction of formula on sheet Genba Check. | C7: JM. Stefanczyk | D7: 42825
A8: A06 | B8: Correction of formula on sheet StEDE3. Perimeter of Sorting precised. Revision level aligned with codification of Quality documents | C8: JM. Stefanczyk / D. Masucci | D8: 42888
A9: B06 | B9: StEDE3 sheet updated to V1.7. Inclusion of Systemic Action in Genbacheck | C9: JM. Stefanczyk / D. Masucci | D9: June 30th, 2017
A10: B07 | B10: Genba Check: StEDE3 assesment removed for Systemic Preventive Action | C10: JM. Stefanczyk / D. Masucci | D10: September 20th, 2017
A11: B08 | B11: Genba Check: cell name changed from "Findings from genba " to "Confirmed on Genba: Supplier / Valeo SQA: Y/N" | C11: JM. Stefanczyk / D. Masucci | D11: December 11th, 2017
A12: B09 | B12: StEDE3 sheet updated to v2.3 | C12: JM. Stefanczyk / D. Masucci / L. Belrose | D12: February 11th, 2020
A13: C01 | B13: PDCA FTA Template Upgrade inline with VIM PDCA FTA Template | C13: Vivekananthan MARAPPAN | D13: Mar 15th, 2021
A14: C02 | B14: SQA Genba Check adopted with formula integration + Quick Response section adopted | C14: Vivekananthan MARAPPAN + Halil-Kurtulus AKGOZ | D14: Mar25th, 2021
A15: C03 | B15: SQA Genba check tab adapted to Action plan Genba review tab + Removal of the word " adjustment " in Step 1 360° Varaibility Hunting in StEDE3 Matrix | C15: JM. Stefanczyk + Vivekananthan MARAPPAN | D15: Jul 12th, 2022
A16: C04 | B16: Wording change about Enforcement : " The Direct Manager checks on genba the respect of the standards and in case a gap is found an action is defined" | C16: JM Clarté | D16: 44995
A17: C05 | B17: Updated StEDE3 workstation assessment result in SQA Genba Check + Updated Data validation in StEDE3 Matrix | C17: Lavanya PALANI | D17: 45096
A18: D01 | B18: Adopted of Supplier StEDE PDCA-FTA Template inline with GST-QU-H01-0007 - B03 | C18: Damian MASUCCI, Jocelyn CONTANT, Lavanya PALANI, Mariusz BURCZAK, Rajendran VINOD | D18: 45638
