Workbook
Name Excel_BuiltIn__FilterDatabase: #REF!
Name HTML_CodePage: 1252
Name HTML_Control: {"'Verr-enseig-ex'!$M$22:$M$23"}
Name HTML_Control: {"'Verr-enseig-ex'!$M$22:$M$23"}
Name HTML_Description: ""
Name HTML_Email: ""
Name HTML_Header: "Verr-enseig-ex"
Name HTML_LastUpdate: "28/07/99"
Name HTML_LineAfter: FALSE
Name HTML_LineBefore: FALSE
Name HTML_Name: "Lee H. Troup"
Name HTML_OBDlg2: TRUE
Name HTML_OBDlg4: TRUE
Name HTML_OS: 0
Name HTML_PathFile: "C:\Mes documents\MonHTML.htm"
Name HTML_Title: "Problem-solving"

Sheet Quick Response 
J1: Customer 8D report
A4: Customer plant | D4: SIIX Hungary Kft | K4: Supplier | M4: AVO CARBON/SAME TUNISIA | S4: Date of claim : | U4: 45450
A5: Customer contact | D5: nikolett.racz@siix-global.com | K5: SAP no. | M5: 0 | S5: Date of QR : | U5: 45450
A6: Claim reference | D6: N° of Alert:QA-045 | K6: Author | M6: Mohamed Naili | S6: Update of QR : | U6: 45496
W7: S2.Fo.S1.8
A8: QUICK RESPONSE
A9: - This document must be validated by Sceet within 24 hours after claim notification / Blue fields filled out by Sceet -
A11: D 1. Description of the problem
B12: 1.a What is the problem ? Use 5W+2H to describe what is the current situation.
B13: Problem description | F13: Tinning length on the coil is out of specification. Allowed size is 4-9 mm | N13: What happened? | R13: Detection of defected parts with tinning length out of specifications
N15: Why is it a problem? | R15: The tinning length is out of specifications
B17: Part number | F17: V02106995 | N17: When did it happen? | R17: 45450
B18: Part description | F18: IND HI CU RAD 6.8 uH 25A R26.5 D16.8x36 | N18: Who detected it? | R18: Costumer
B19: Traceability of nok parts | N19: Where was it detected? | R19: SIIX Hungary plant
B20: Recurrence | F20: No | N20: How was it detected? | R20: Dimensional Measurement
B21: Defect S/R | F21: NA | N21: How many parts ? | R21: 4 parts
B23: nok part picture / sketch | D23: Bad Part : tinning lengt is out of drawing specification ( Allowed size is 4-9 mm) | N23: ok part picture / sketch | P23: Good Part : tinning lengt is compliant with the drawing specification ( Allowed size is 4-9 mm)
B32: 1.b Problem solving team
B33: Name | G33: Position | L33: Location | O33: Telephone | S33: Email
B34: Slah S. | G34: Quality engineer | L34: Same Tunisia | O34: 21658588814 | S34: slah.saoudi@avocarbon.com
B35: Nabil Z. | G35: Production supervisor | L35: Same Tunisia | O35: 21658024950 | S35: prod.same@avocarbon.com
B36: Ibrahim A. | G36: Quality process technician | L36: Same Tunisia | S36: qualite.same@avocarbon.com
B37: Mortadha T. | G37: Method engineer | L37: Same Tunisia | O37: 21655092279 | S37: mortadha.touhemi@avocarbon.com
B38: Mohamed BO. | G38: Winding Area supervisor | L38: Same Tunisia | S38: bobinage.same@avocarbon.com
B39: Wael Ch. | G39: Chokes PLM | L39: Same Tunisia | O39: 21658049078 | S39: wael.charaabi@avocarbon.com
B40: Mohamed N. | G40: Quality M | L40: Same Tunisia | O40: 21628373744 | S40: mohamed.naili@avocarbon.com
B42: 1.c Tool to use (defined by SAME)
C43: X | D43: Ishikawa | F43: X | G43: FTA | I43: X | J43: 5why's | M43: Audit | P43: Other
B44: 1.d Problem description from customer / first analyse of problem / potential root causes
B45: Variability on winding process
B48: Samples of nok parts required at customer location | Q48: Express shipping customer account
A51: D 2. Risk on similar products and processes | L51: No
B52: Can this defect happen on similar parts ? | Q52: Comments (compulsory if yes)
B53: Other family product | F53: No
B54: Other machine | F54: No
B55: Other tooling | F55: No
B56: Other | F56: NA
A59: D 3. Containment | P59: see sorting approval
B60: What are the actions to detect all non-conforming parts in the process flow ?
B61: Location in the process flow | I61: Nb to be sorted | L61: Nb parts sorted | O61: Nb nok parts | R61: ppm | U61: Date | W61: Resp.
...

Sheet D4-D8
J1: Supplier 8D report | R1: supplier logo
A4: Customer plant | E4: SIIX | K4: Supplier | M4: ='Quick Response '!M4 -> AVO CARBON/SAME TUNISIA | S4: Date of claim | V4: 45450
A5: Customer contact | K5: SAP no. | M5: ='Quick Response '!M5 -> 0 | S5: Date of D4-D8 | V5: 45485
A6: Claim reference | K6: Author | M6: ='Quick Response '!M6 -> Mohamed Naili | S6: Update of D4-D8 | V6: 45496
A8: ANALYSE AND COUNTERMEASURES (D4-D8)
S9: Commitment date from the supplier to send D4-D5-D6 (to be filled in with the quick response) : | T9: 45485
A11: D 4. Root cause of occurrence | M11: Ishikawa | Q11: FTA | U11: 5 why's
B12: Work out the root causes using first Ishikawa, then FTA and finally 5 why's (Tools to use chosen by Sceet).
B14: Root cause of occurrence :
B15: 1- Slide of the wire during coil winding steps : bad maintaining of wire 2- Slide of the wire during coil winding steps : 0vibration due to bad alignement of the spindle
B20: How was the defect reproduced ?
B21: Evaluate variability of tinning length variaility when bad holding of the wire durin coil winding steps also due to alignement issue of spindle axis according to motor axis
A25: D 5. Root cause of non detection | M25: Ishikawa | Q25: FTA | U25: 5 why's
B26: Work out the root causes using first Ishikawa, then FTA and finally 5 why's (Tools to use chosen by Sceet).
B28: Root cause of non detection :
B29: 1- Bad tinning length monitoring process definition 2- standard of tinning length inspection was not respected at EOL Work station
A35: D 6. Countermeasure to non detection and occurrence
B36: Actions | P36: Resp. | S36: Date plan. | V36: Date clos.
B37: 1) Change Winding Process Sequence : Add a holding device to secure the wire during winding and improve accuracy by implementing additional deviceo ensure the correct wire stripping length | P37: Wael | S37: 45483 | V37: 45483
B38: 2) Add a guide pin to the spindle to prevent slipping and sliding during the winding operation. | P38: Wael | S38: 45485 | V38: 45485
B39: 3) Regular Preventive Maintenance Checks: Add a regular maintenance plan to inspect and adjust the spindle and its supports, ensuring they remain in proper working condition. | P39: Wael | S39: 45485 | V39: 45485
B40: 4) Create a parameter card that specifies the optimal parameters for tinning length...to ensure the correct settings are used and to maintain consistency...(Cofirmed with capability reports and process stability assessments) 5) Add a Regular checks of parametre card in preventive maintenance plan to detect any deviations and ensure that the process remains within acceptable limits | P40: Wael | S40: 45489 | V40: 45489
B41: 6) Update winding SOP-EOP valdation checklist and SPC card : adjustement of tinning length from 7,5±0,5mm to 6±0,5 mm | P41: Slah S | S41: 45496 | V41: 45496
B42: 7) Update ERP (QMES) SOP -EOP checklist and SPC card : Adjustement of tinning length from 7,5±0,5 mm to 6±0,5 mm | P42: Slah S | S42: 45496 | V42: 45496
A48: D 7. Effectiveness of action plan
B49: Actions to check effectiveness (to plan with part D6) | P49: Resp. | S49: Date plan. | V49: Date clos.
B50: Capability study of tinning length | P50: Slah S | S50: 45496 | V50: 45496
B51: Capability study of stripping length | P51: Slah S | S51: 45496 | V51: 45496
A57: D 8. Lessons learned
B58: 8.1 Do following documents require an update ? | M58: 8.2 Generalization of countermeasures to similar lines/ products
F59: Resp. | H59: Date plan. | J59: Date clos. | M59: NA
B60: PFMEA | F60: Slah S | H60: 45496 | J60: 45496
B61: Control Plan | F61: Slah S | H61: 45496 | J61: 45496
B62: Work instruction | F62: Mortadha T. | H62: 45496 | J62: 45496 | M62: 8.3 Audit done by supplier (if required)
B63: Control instruction | M63: Date | N63: NA | R63: Results
B64: Procedure | M64: Comments
B65: Control gage
B66: Maintenance instruction | F66: Wael Ch | H66: 45496 | J66: 45496
B67: Lesson Learned Card
B68: Other | C68: Maintenance stock
...

Sheet Ishikawa
I1: Ishikawa Diagram
A2: Customer plant | J2: Supplier | L2: ='Quick Response '!M4 -> AVO CARBON/SAME TUNISIA | R2: Date of claim | S2: 45450
A3: Customer contact | J3: SAP no. | L3: ='Quick Response '!M5 -> 0 | R3: Date of D4-D8 | S3: 45485
A4: Claim reference | J4: Author | L4: ='Quick Response '!M6 -> Mohamed Naili | R4: Update of D4-D8 | S4: 45496
S5: Occurence
B6: Material | G6: Work environment | N6: Method
S18: Problem
S19: Tinning length out of specifications (> 9mm )
B25: Stripping Proces
F29: Slide of the wire during coil winding steps
C37: Machine | H37: Manpower | N37: Measurement
S40: Non Détection
B41: Material | G41: Work environment | N41: Method
P45: Inspection at Final control WS
Q49: SOP Validation
S53: Problem
S54: Tinning length out of specifications (> 9mm )
Q65: Detection with measurement devices
C72: Machine | H72: Manpower | N72: Measurement

Sheet FTA
E1: Factor Tree Analysis | J1: SUPPLIER LOGO | P1: Yes
A2: Customer plant | E2: Supplier | F2: ='Quick Response '!M4 -> AVO CARBON/SAME TUNISIA | I2: Date of claim | J2: 45450 | P2: No
A3: Customer contact | E3: SAP no. | F3: ='Quick Response '!M5 -> 0 | I3: Date of FTA | J3: 45463
A4: Claim reference | E4: Author | F4: ='Quick Response '!M6 -> Mohamed Naili | I4: Update of FTA | J4: 45496 | P4: Doubt
A6: Problem description: | C6: ='Quick Response '!F13 -> Tinning length on the coil is out of specification. Allowed size is 4-9 mm
A7: Factor Nb | B7: Factors | C7: Control point | D7: Standard | E7: OK parts | F7: NOK parts | G7: Std meet | H7: Std OK | I7: Action to reproduce the defect | J7: Resp. | K7: Date | L7: Def. rep. | M7: Direct link ?
A8: OCCURENCE | O8: Assignement
A9: 1 | B9: Stripping process | C9: Check conformity of stripping depth at SOP / EOP Check conformity of stripping length at SOP /EOP | D9: Stripping depth = [1,87 to 1,94] (mm) Stripping length = [14 to 16] (mm) No stripping aspect issues (Varnish) | E9: no stripping aspect issues (varnish) Stripping length (the sum of the two legs tinning area) < 18 mm | F9: no stripping aspect issues (varnish) Stripping length (the sum of the two legs tinning area) < 18 mm | G9: Yes | H9: Yes | I9: Evauate variability on stripping length | J9: Slah S. | K9: 45453 | L9: No | M9: No | O9: No variability was detected in stripping process : stripping length still always in the fixed limits
A10: 2 | B10: Slide of the wire during coil winding steps | C10: wire holding system maintain wire steady during coil winding steps | D10: wire do not slide when maintained by the cylinder and the beak of the spindle during coil winding steps | E10: Tinning length of each leg < 9mm , the sum of tinning length of two legs <= 18mm | F10: Maxiumum tinning length measured fro each leg up to 9mm The sum of two leg tinning length <=18mm | G10: No | H10: No | I10: Evaluate variability of tinning length variaility when bad holding of the wire durin coil winding steps | J10: Wael CH. | K10: 45468 | L10: Yes | M10: Yes | O10: Tinning length issue occurs when bad holding - maintaining of the wire during coil winding steps
A11: 3
A12: 4
A13: 5
A14: 6
A16: 8
A17: NON DETECTION
A18: 1 | B18: Tinning length inspection at Final control work station | C18: Check tinninng length of each leg at EOL WS | D18: Check 100% with gauge the tinning length for each coil leg Tinning area must be from 4 to 9mm (operation #7) | E18: 100% of coils with tinning length out oif specification are captured by gauge at EOL WS | F18: not all coils with tinning length out of specification are captured at EOL WS (bad parts with tinning length > 9mm are captured at customer plant) | G18: No | H18: Yes | I18: Evaluate detection of bad parts at EOL WS | J18: Slah S. | K18: 45483 | L18: Yes | M18: Yes | O18: 2 parts from 12 parts with tinning length up to 9mm was not captured at EOL WS
A19: 2 | B19: Detection with measurement devices | C19: Check conformity of tinning length with gauge | D19: Tinning length is checked by gauge at coil winding process step | E19: Coils with tinning length out of specification are 100% captured by gauge | F19: Coils with tinning length out of specifications are 100% captured by gauge | G19: Yes | H19: Yes
A20: 3 | B20: Bad SOP validation | C20: Check tinning length conformity at SOP validation | D20: Tinning length <= 9mm Tinning length is Checked by gauge | E20: Tinning length measured on SOP validation parts < 9mm | F20: Tinning length measured on SOP validation parts < 9mm | G20: Yes | H20: Yes
A21: 4 | B21: Tinning length monnitoring process | C21: check the conformity of parts at SOP - EOP Check stability of the proocess Each 4 hours process is always under control | D21: Tinning length is checked at SOP - EOP Each 4 hours by SPC Process capability Cp/Cpk > 1.67 / 2 When deviation accors, process is stopped before producing bad parts | E21: 100% of parts produced are with Tinning length is under specification when deviation of tinning length process occur. production is stopped and adjustement is done | F21: tinning length Process deviation is not captured when applying monitoring process Cp =1,727 Cpk = 0,742 | G21: Yes | H21: No | I21: check 100% of tinning length variability during 2 hours of prouction | J21: Slah S. | K21: 03/07/204 | L21: Yes | M21: Yes | O21: 15 parts from 960 pcs with tinning length out of specification was detected during production of 2 hours
M26: All validated causes (direct link or doubt) must lead to a 5 Why's analysis

Sheet 5why's
G1: 5 Why's | I1: SUPPLIER LOGO
A2: Customer plant | E2: Supplier | G2: ='Quick Response '!M4 -> AVO CARBON/SAME TUNISIA | I2: Date of claim | K2: 45450
A3: Customer contact | E3: SAP no. | G3: ='Quick Response '!M5 -> 0 | I3: Date of 5 why's | K3: 45485
A4: Claim reference | E4: Author | G4: ='Quick Response '!M6 -> Mohamed Naili | I4: Update of 5 why's | K4: 45496
B7: Problem description : | C7: ='Quick Response '!F13 -> Tinning length on the coil is out of specification. Allowed size is 4-9 mm
A8: Factor nb | B8: Relevant factors from FTA | C8: 1st WHY? | D8: Check | E8: 2nd WHY ? | F8: Check | G8: 3rd WHY ? | H8: Check | I8: 4th WHY ? | J8: Check | K8: 5th WHY ? | L8: Check
A9: OCCURENCE
A10: 1 | B10: Bad maintaining of the wire during coil winding Process (Holding of the wire on the spindle ) | C10: Wire sliding during winding operation | E10: The spindle is not properly aligned. It is either moving or not securely fixed, leading to vibrations during winding operations | G10: There is no secure mechanism to keep the spindle in place (e.g., guide or fixing pin) | I10: Because the initial design specifications did not account for potential slipping during the winding process. | J10: >
A11: 2 | B11: Sliding of the wire during the stripping operation | C11: The wire is not secured properly during winding | E11: The current winding setup did not include a device to secure or maintain the wire position accurately... | G11: There was no effective mechanism in place to hold the wire in place during the winding operation (There is no holding device in place to keep the wire steady) | I11: The process was designed without considering sliding of wire diametre over than 1.7 mm (variations in wire diameter and tension) | J11: >
L12: >
A16: NON DETECTION
A17: 1 | B17: Parts with tinning length out of specification were not captured at EOL WS | C17: Inspection of tinning length with gauge was done by sampling instead 100% | E17: Only juged suspected parts were checked by gauge | G17: no variability of tinning length process was ocuured frequently
A18: 2 | B18: Bad Tinning length monnitoring process | C18: inspection frequency was set based on internal specification despite no customer implicit or explicit requirement (no special characteristic was defined in the specification related to tinning length) | E18: poka-yoke device (camera) was set to 100% check stripping length variability by the way tinning length variability | G18: tinning length varibility was occured by wire maintaing system separately of stripping length process variability | I18: Risk was not assessed
A23: 'Check' box: Verification is done based on tests, measurements & data to confirm root cause. > : cause is confirmed x : not root cause

Sheet Winding SOP validation update 
A6: Tinning length and stripping length update on internal ERP

Sheet Capability of tinning length 
D1: Tinning length process capability (before) (Jan 2024 -June 2024)
S2: Tinning length process capability (after ) (July 2024)
D30: Cp =1,727
D31: Cpk = 0,742

Sheet LLC
D1: Lesson Learned Card | J1: SUPPLIER LOGO
A4: Customer plant | C4: =#REF! -> #REF! | E4: Supplier | G4: =#REF! -> #REF! | I4: LLC Type | J4: Detection | K4: Logistics
A5: Claim reference | C5: =#REF! -> #REF! | E5: Author | J5: Occurrence | K5: Process
A6: Date of incident | C6: =#REF! -> #REF! | E6: Date of LLC | J6: Management | K6: Product
A8: 1. WHAT WAS THE PROBLEM? (5W + 2H) | G8: 2. WHAT IS THE CAUSE?
A9: What happened ?
A10: =#REF! -> #REF!
A11: Why it is a problem ?
A12: =#REF! -> #REF!
A13: When did it happen ?
A14: =#REF! -> #REF!
A15: Who has detected it ?
A16: =#REF! -> #REF!
A17: Where has been detected ?
A18: =#REF! -> #REF!
A19: How has it been detected ?
A20: =#REF! -> #REF!
A21: How many ?
A22: =#REF! -> #REF!
A24: 3. DESCRIPTION OF THE APPLIED MODIFICATION
A25: BEFORE | G25: AFTER
A26: Add a picture or a descriptive graph which explains the conditions that led to the problem | G26: Add a picture or a descriptive graph which explains the countermeasure on the part/process IMPORTANT : "AFTER" picture or graph should be SIMILAR (same point of view, same size) to "BEFORE" picture
A28: 4) WHAT WE LEARNED?
A29: ERADICATION What is the countermeasure that was put in place to avoid recurrence ? | E29: CHECKING What is the method (who, what, how) for the countermeasures? | I29: SIGNALING What is the countermeasure supposed to do or make or hightlight when detecting a non conformity ?
A38: 5. WHAT HAS BEEN MODIFIED ?
A39: a. Proces is modified according to Before/ After sheet | B39: b. All documents have been updated and has been validated with the operators | C39: c. Procedures and work instructions | D39: d. Control Plan and PFMEA | E39: e. Maintenance instructions | F39: f. Records (start-up checklists, reaction sheets, preventive maintenance...) | G39: g. Visual aids are posted | H39: h. Operators and other functions are trained | I39: i. Proof of training is avalaible (records,5 ' meeting) | J39: j. Operators can correctly describe what they must do | K39: k. Other: | L39: l. Other:
A41: 6. POTENTIAL APPLICABILITY
A42: Product :
A43: Line / process :
A44: Plant :

Sheet Sorting approval
J1: Supplier 8D report | R1: supplier logo
A4: Customer plant | F4: =#REF! -> #REF! | K4: Supplier | M4: =#REF! -> #REF! | S4: Date of claim
A5: Customer contact | F5: =#REF! -> #REF! | K5: SAP no | M5: =#REF! -> #REF! | S5: Date of page
A6: Claim reference | F6: =#REF! -> #REF! | K6: Author | M6: =#REF! -> #REF! | S6: Update
A8: APPROVAL OF SORTING / REWORK
B9: -This document must be sent to AVO/Same within | N9: 5 | O9: hour(s) after claim notification - | AC9: 1
AC10: 2
AC11: 3
B12: Claim issuer | N12: Claim receiver | AC12: 5
B13: Name | N13: Name | AC13: 8
B14: Position | N14: Position | AC14: 12
B15: Telephone | N15: Telephone | AC15: 24
B16: Fax | N16: Fax
B17: Email | N17: Email
A20: Immediate actions required at Sceet
B22: Problem description
B23: =#REF! -> #REF!
B26: Description of sorting/rework
B31: Quantity and part numbers concerned
B32: Location in the process flow | I32: Quantity | L32: Part number(s) concerned
B33: Parts at SAME plant | I33: =#REF! -> #REF!
B34: Parts at SAME logistics platform | I34: =#REF! -> #REF!
B35: Parts at SAME's customer (C1) | I35: =#REF! -> #REF!
B36: Parts in transport | I36: =#REF! -> #REF!
B38: Sorting company chosen to do the sorting/rework
B39: Name | N39: Tel.
B40: Location | N40: Fax
B41: Contact | N41: Email
B44: Comments from Sceet
B45: All costs for semi-finished goods and finished goods with nok components will be invoiced to the supplier. Nok components will be returned to the supplier.
A51: Supplier's approval to accept responsibility for the defect and related costs
B59: Name of authorized person | J59: Signature | R59: Date
B64: Approvals have to be given in written format !
