Workbook
Name feuille_list: INDIRECT([2]param!$F$22)
Name NEWNOK__: 'SQA Genba Check'!$AK$14:$AK$15
Name NEWOK__: '[3]SQA Genba Check'!$AK$13:$AK$14
Name NEWOK__: 'SQA Genba Check'!$AK$13:$AK$14
Name TB__: #N/A
Name TC__: #N/A
Name TD__: #N/A
Name TE__: #N/A
Name TF__: #N/A
Name TG__: #N/A
Name TH__: #N/A
Name TI__: #N/A
Name TJ__: #N/A
Name TK__: #N/A
Name TL__: #N/A
Name TM__: #N/A

Sheet Comments on content expectation
A1: Language/Idioma/Langue/Lingua/Język/语言...etc:
B3: =IFERROR(__xludf.DUMMYFUNCTION("IMPORTRANGE(""https://docs.google.com/spreadsheets/d/1LUmYcQDWNJrUScJfWrqXWxJ7uWSU668YPR7jSkYjsPo/edit#gid=477872199"",""PDCA/FTA comments!B1:AC"")"),"#REF!") -> #REF! | C3: -attentes de contenu") | D3: -Expectativas de Conteúdo") | E3: -expectativas de contenido") | F3: -内容预期") | G3: -Obsah") | H3: -Inhalt Erwartungen") | I3: -Tartalmi elvárások") | J3: -harapan konten") | K3: -Spiegazione del contenuto") | L3: -内容に関する期待値") | M3: -요구 내용") | N3: -oczekiwania treści") | O3: -așteptările de conținut") | P3: -Ожидания по содержанию") | Q3: -ความคาดหวังของเนื้อหา") | R3: -İçerik beklentiler")
B4: -English") | C4: -Français (Googletranslate)") | D4: -PORTUGUÊS") | E4: -Spanish (Googletranslate)") | F4: -Chinese Simplified - Translated ") | G4: -Czech") | H4: -German (Googletranslate)") | I4: -Hungarian (Googletranslate)") | J4: -Indonesian (Googletranslate)") | K4: -Italian - Completed") | L4: -Japanese - Completed") | M4: -Korean - Completed") | N4: -Polish (Googletranslate)") | O4: -Romanian (Googletranslate)") | P4: -Russian ") | Q4: -Thai (Googletranslate)") | R4: -Turkish (Googletranslate)")
B5: -Quick Response PDCA") | C5: -Quick Response PDCA") | D5: -Resposta Rápida PDCA") | E5: -Respuesta rápida PDCA") | F5: -快速响应PDCA") | G5: -Quick Response PDCA") | H5: -Quick Response PDCA") | I5: -Gyors válasz PDCA") | J5: -Quick Response PDCA") | K5: -Quick Response PDCA") | L5: -クイックレスポンスPDCA") | M5: -Quick Response PDCA") | N5: -Szybka reakcja PDCA") | O5: -Quick Response PDCA") | P5: -Быстрая реакция PDCA") | Q5: -ตอบสนองอย่างรวดเร็ว PDCA") | R5: -Hızlı Yanıt PUKÖ")
A6: [1] | B6: Customer / contact name Enter the customer affected and the contact name at the customer with his phone number and /or his E mail") | C6: -Client / Nom de contact Entrez le client affecté et le nom du contact chez le client avec son numéro de téléphone et / ou son e-mail") | D6: -Cliente / Nome do contato Insira o cliente afetado e o nome de contato do cliente com seu número de telefone e / ou seu e-mail") | E6: -Nombre del cliente / contacto Introduzca el cliente afectado y el nombre del contacto al cliente con su número de teléfono y / o su mail Correo") | F6: -客户/联系人姓名 输入影响到的客户和对应联系人姓名及他们的电话号码和/或电子信箱。") | G6: -Zákazník / jméno kontaktní osoby Vstoupit zákazníka postiženého a jméno kontaktní osoby u zákazníka se svým telefonním číslem a / nebo jeho E mailem") | H6: -Kunden- / Kontaktnamen Geben Sie die betroffenen Kunden und die Kontaktnamen beim Kunden mit seiner Telefonnummer und / oder seiner E Mail an") | I6: -Vevő / kapcsolattartó neve Írja be az ügyfél az érintett és a kapcsolattartó nevét az ügyfél a telefonszámát és / vagy a E-mail") | J6: -Pelanggan / nama kontak Masukkan pelanggan yang terkena dampak dan nama kontak di pelanggan dengan nomor telepon dan / atau surat E-nya") | K6: -Cliente / nome del contatto Inserisci il cliente interessato e il nome del contatto presso il cliente con il suo numero di telefono e / o il suo E mail") | L6: -顧客/連絡先名 影響を受けた顧客ならびに、その電話番号および/またはEメールアドレスを入力") | M6: -고객 / 연락처 이름 고객 이름, 연락 가능한 전화번호 또는 이메일 주소를 입력") | N6: -Klient / nazwisko osoby kontaktowej Wprowadź klientowi dotyczy i nazwę kontaktu u klienta z jego numer telefonu i / lub jego poczty E") | O6: -Clienți / Numele persoanei de contact Introduceți clientul afectat și numele de contact de la client cu numărul său de telefon și / sau e-mail lui E") | P6: -Наименование потребителя / контактное лицо Укажите наименование потребителя, у которого случилась проблема, и имя контактного лица у потребителя с его номером телефона и/или электронной почтой ") | Q6: -ลูกค้า / ชื่อผู้ติดต่อ ใส่ชื่อลูกค้าได้รับผลกระทบและชื่อผู้ติดต่อของลูกค้าพร้อมกับหมายเลขโทรศัพท์ของเขาและ / หรืออีเมล์ของเขา") | R6: -Müşteri / kişi adı onun telefon numarası ve / veya onun e posta ile müşteriye de müşteri etkilenen ve kişi adını girin")
A7: [2] | B7: Product (Designation + Ref) VALEO Indicate the designation and the Valeo part number of the concerned part") | C7: -Produit (Désignation + Ref) VALEO Indiquer la désignation et le numéro de référence Valeo de la partie concernée") | D7: -Produto (Designação + Ref) VALEO Indique a designação e o número da peça Valeo da peça em questão") | E7: -Producto (Designación + Ref) VALEO Indicar la designación y el número de pieza Valeo de la parte en cuestión") | F7: -法雷奥产品（名称+零件号） 指出所涉及到的零件,写清零件名称和法雷奥零件号。") | G7: -VALEO Produkt (Název + Reference) Uveďte název a číslo dílu dotčeného Valeo produktu") | H7: -Produkt (Bezeichnung + Ref) VALEO Geben Sie die Bezeichnung und die Valeo-Teilenummer des betreffenden Teils an") | I7: -Termék (kijelölés + Ref) VALEO Jelölje meg a kijelölés és a Valeo cikkszáma az érintett rész") | J7: -Produk (Penunjukan + Ref) VALEO Menunjukkan penunjukan dan Valeo nomor bagian dari bagian yang bersangkutan") | K7: -Prodotto (Denominazione + Ref) VALEO Indicare la denominazione e il numero di riferimento Valeo della parte interessata") | L7: -VALEOにおける製品名（種類+ 使用用途等） 製品種類や製品使用用途、不具合品のVALEO品番を記入") | M7: -발레오 제품 (지정 + 참조) 품명 및 관련 부품의 발레오 부품 번호") | N7: -Produkt (oznaczenie + Ref) VALEO Wskazać oznaczenie i numer katalogowy Valeo z danej części") | O7: -Produs (Denumire + Ref) VALEO Se indică denumirea și numărul Valeo parte a părții în cauză") | P7: -Продукт (обозначение + референс) VALEO Укажите наименование и Valeo номер детали для соответствующей детали") | Q7: -ผลิตภัณฑ์ (ชือผลิตภัณฑ์ + การอ้างอิง) VALEO ระบุชื่อผลิตภัณฑ์และหมายเลขผลิตภัณฑ์วาลีโอ ของชิ้นส่วนที่เกี่ยวข้อง") | R7: -Ürün (Adı + Referans) VALEO atamasını ve ilgili parçanın Valeo parça numarasını belirtiniz")
A8: [3] | B8: Origin Tick the appropriate box(es) according to the type of issue ") | C8: -Origine Cochez la case appropriée (s) en fonction du type d'émission") | D8: -Origem Marque a (s) caixa (s) apropriada (s) de acordo com o tipo de problema") | E8: -Origen Marque la casilla apropiada (es) de acuerdo con el tipo de problema") | F8: -起因 根据问题类型勾选相应的框。") | G8: -Původ Zaškrtněte vhodné možnosti v závislosti na typu problému") | H8: -Ursprung Markieren Sie das (die) entsprechende(n) Feld(er) nach der Art der Ausgabe") | I8: -Eredet Jelölje meg a megfelelő négyzet (ek) szerint a probléma típusát") | J8: -Asal Centang kotak yang sesuai (es) sesuai dengan jenis masalah") | K8: -Origine Barrare le caselle appropriate a seconda del tipo di problema") | L8: -区分 問題の種類に応じて、適切な欄を選択") | M8: -유래 문제의 종류에 따라 해당 박스(들) 선택") | N8: -Pochodzenie Zaznacz pole wyboru odpowiedniego (ES) w zależności od rodzaju emisji") | O8: -Origine Bifați căsuța corespunzătoare (ES) în funcție de tipul de emisiune") | P8: -Происхождение Отметьте соответствующие поля в соответствии с типом проблемы") | Q8: -ที่มา กาเครื่องหมายในช่องที่เหมาะสม ตามประเภทของปัญหา") | R8: -Menşei sorunun türüne göre uygun kutuyu (ler) Tick")
A9: [4] | B9: What happened? - Description of the problem with clear and precise facts as defined by the customer. - Recurrence information - Traceability elements of the defective parts") | C9: -Qu'est-il arrivé? - Description du problème avec des faits clairs et précis, tels que définis par le client. - informations Récurrence - les éléments de traçabilité des pièces défectueuses") | D9: -O que aconteceu? - Descrição do problema com fatos claros e precisos definidos pelo cliente. - Informações de recorrência - Elementos de rastreabilidade das peças defeituosas") | E9: -¿Que pasó? - Descripción del problema con hechos claros y precisos definidos por el cliente. - información de periodicidad - elementos de trazabilidad de las piezas defectuosas") | F9: -发生了什么？ - 用客户定义的清楚、准确的事实来描述问题. - 再发信息 - 缺陷零件的可追溯性信息") | G9: -Co se stalo? - Popis problému s jasnými a přesnými fakty jak je popisuje zákazník. - Informace o opakovaném problému - Způsob dohledatelnosti vadných dílů (označení dohledatelnosti)") | H9: -Was ist passiert? - Beschreibung des Problems mit klaren und genauen Fakten, wie vom Kunden definiert. - Informationen bzgl. Wiederauftreten - Rückverfolgbarkeit Elemente der defekten Teile") | I9: -Mi történt? - A probléma leírása egyértelmű és pontos tények által meghatározott ügyfél. - Az ismétlődés információk - nyomon követhetőség elemei hibás alkatrészek") | J9: -Apa yang terjadi? - Deskripsi masalah dengan fakta-fakta yang jelas dan tepat seperti yang didefinisikan oleh pelanggan. - Informasi Kambuh - elemen Lacak bagian yang rusak") | K9: -Cosa è successo - Descrizione del problema con i fatti chiari e precisi, come definito dal cliente - Informazioni sulla rioccorenza - Tracciabilità dei pezzi difettosi") | L9: -何が起こったか？ - 顧客によって定義された問題事象について明瞭かつ正確な事実に基づいて記述 - 再発情報 - 不具合部品のトレーサビリティ要素") | M9: -어떤 일이 발생하였습니까? - 고객에 의해 정의 된 명확하고 정확한 사실에 의거하여, 문제 설명 - 재발 정보 - 부적합 제품 추적 정보") | N9: -Co się stało? - Opis problemu z jasnych i precyzyjnych faktów określonych przez klienta. - informacja Nawrót - elementy identyfikowalność wadliwych części") | O9: -Ce s-a întâmplat? - Descrierea problemei cu fapte clare și precise, astfel cum sunt definite de către client. - informații Recurența - elemente Trasabilitatea pieselor defecte") | P9: -Что случилось? - описание проблемы с ясными и точными фактами, определенными потребителем - информация о повторении проблемы - прослеживаемость дефектных деталей") | Q9: -อะไร เกิดขึ้น? - รายละเอียดของปัญหาที่เกิดขึ้น กับข้อเท็จจริงที่ชัดเจนและแม่นยำตามที่กำหนดโดยลูกค้า - ข้อมูลการเกิดซ้ำ - องค์ประกอบตรวจสอบย้อนกลับของชิ้นส่วนที่บกพร่องเสียหาย") | R9: -Ne oldu? - müşteri tarafından tanımlanan net ve kesin gerçeklerle Sorunun açıklaması. - Tekrarlama bilgiler - hatalı parçaların izlenebilirlik elemanları")
A10: [5] | B10: Why is it a problem? In this section we need to understand what the impact of the problem is for the assembly site and/or for the final Customer. Those elements must be quantified (data) - What is the Customer effect of the defect ? - Impact on the logist"&"ic management of the part - Impact on the handling of the part - Impact on the assembly of the part - Technical impact in the application - Impact on the product reliability - Impact in term of safety - regulation - How important is the problem?") | C10: -Pourquoi est-il un problème? Dans cette section, nous devons comprendre l'impact du problème est pour le site d'assemblage et / ou pour le client final. Ces éléments doivent être quantifiés (données) - Quel est l'effet client du défaut? - Impact sur la ge"&"stion logistique de la partie - Impact sur la manipulation de la partie - Impact sur l'ensemble de la partie - Impact technique dans l'application - Impact sur la fiabilité du produit - Impact en terme de sécurité - réglementation - Quelle est l'importanc"&"e du problème?") | D10: -Por que isso é um problema? Nesta seção, precisamos entender qual é o impacto do problema para o local de montagem e / ou para o cliente final. Esses elementos devem ser quantificados (dados) - Qual é o efeito do defeito para o cliente? - Impacto na gestã"&"o logística da peça - Impacto no manuseio da peça - Impacto na montagem da peça - Impacto técnico na aplicação - Impacto na confiabilidade do produto - Impacto em termos de segurança - regulamentação - Quão importante é o problema?") | E10: -Por qué es un problema? En esta sección tenemos que entender lo que el impacto del problema es que el sitio de montaje y / o para la final al cliente. Esos elementos deben ser cuantificados (datos) - ¿Cuál es el efecto del cliente del defecto? - Impacto e"&"n la gestión logística de la parte - Impacto en el manejo de la parte - Impacto en el montaje de la parte - impacto técnico en la aplicación - Impacto sobre la fiabilidad del producto - Impacto en términos de seguridad - Reglamento - ¿Qué tan importante e"&"s el problema?") | F10: -为什么是一个问题？ 在这个模块,我们需要明白问题对装配工厂和/或终端使用者所产生的影响, 下面这些要素必须要量化(数据) - 缺陷会对客户产生什么样的影响？ - 对零件物流管理的影响 - 对零件处理的影响 - 对零件装配的影响 - 对应用的技术影响 - 对产品可靠性的影响 - 对安全-法规的影响 - 问题有多严重") | G10: -Proč je to problém? V této částije třeba pochopit, jaké dopady má tento problém v montážním závodě a/nebo pro konečného zákazníka (řidič). Tyto dopady musí být kvantifikovány (data) - Jaký je efekt problému u zákazníka? - Dopad na logisticku výrobku - Dop"&"ad na manipulaci s výrobkem - Dopad na montáž výrobku - Technický dopad v aplikaci výrobku - Dopad na spolehlivost výrobku - Dopad z hlediska bezpečnosti - regulace (S/R) - Jak důležitý je tento problém?") | H10: -Warum ist das ein Problem? In diesem Abschnitt müssen wir verstehen, was die Auswirkungen des Problems für das Produktionswerk und / oder für die Endkunden sind. Diese Elemente müssen quantifiziert (Daten) werden - Was ist die Auswirkung dieses Mangels fü"&"r den Kunden? - Auswirkungen auf das Logistik-Management des Teils - Auswirkungen auf die Handhabung des Teils - Auswirkungen auf die Montage des Teils - Technische Auswirkungen in der Anwendung - Auswirkungen auf die Zuverlässigkeit des Produktes - Auswi"&"rkungen in der Bezeichnung der Sicherheits - Verordnung - Wie wichtig ist das Problem?") | I10: -Miért probléma? Ebben a részben meg kell értenünk, hogy mi milyen hatással van a probléma a szerelés helyszínén és / vagy a végső fogyasztót. Ezeket az elemeket kell számszerűsíteni (adatok) - Mi az Ügyfél hatása a hiba? - hatása a logisztikai menedzsment"&" a rész - gyakorolt ​​hatás kezelése a rész - hatása a szerelvény a rész - Műszaki hatás az alkalmazás - Hatás a termék megbízhatóságát - Ütközés távú biztonság - szabályozás - Mennyire fontos a probléma?") | J10: -Mengapa masalah? Pada bagian ini kita perlu memahami apa dampak dari masalah adalah untuk situs perakitan dan / atau untuk Pelanggan akhir. Unsur-unsur harus diukur (data) - Apa efek Nasabah cacat? - Dampak terhadap manajemen logistik dari bagian - Dampak"&" terhadap penanganan bagian - Dampak pada perakitan bagian - Dampak Teknis dalam aplikasi - Dampak terhadap keandalan produk - Dampak dalam hal keselamatan - regulasi - Seberapa penting masalah?") | K10: -Perché è un problema? In questa sezione bisogna spiegare quale sarà l'impatto del problema per il sito di assemblaggio e / o per il cliente finale. Tali elementi devono essere quantificati (dati) - Quale effetto la non conformità genera sul Cliente? - Imp"&"atto sulla gestione logistica - Impatto sulla movimentazione del prodotto - Impatto sul montaggio del prodotto - impatto tecnico nell'applicazione - Impatto sulla affidabilità del prodotto - Impatto in termini di Sicurezza - Regolamentazione - Quanto è im"&"portante il problema?") | L10: -なぜそれが問題ですか？ このセクションでは、問題の影響が、生産工場および/または最終顧客にどのような影響を及ぼすか理解する必要があります。これらの要素は、数値定量化されなければならない（データ） - 不具合の顧客への影響は何か？ - 物流・生産管理への影響 - 製品・部品取扱い上の影響 - 製品・部品生産上の影響 - 技術的な見地に関する影響 - 製品の信頼性への影響 - 安全性のへの影響 - 規制に係るか？ - 問題はどの程度の重要性か？") | M10: -왜 문제 입니까? 본 내용에서, 우리는 해당문제가 조립 공장 그리고/또는 최종 고객에 어떤 영향을 끼치는지 이해할 필요가 있습니다. 아래 내용은 반드시 정량화되어야 합니다. - 고객에 미치는 영향은 무엇입니까? - 물류관리에 미치는 영향? - 취급에 미치는 영향? - 조립에 미치는 영향? - 응용 프로그램의 기술에 미치는 영향? - 제품 신뢰성에 미치는 영향? - 안전 / 법규에 미치는 영향? - 얼마나 중요한 문제입니까?") | N10: -Dlaczego jest to problem? W tym punkcie musimy zrozumieć jaki wpływ problemu jest na miejscu montażu i / lub dla klienta końcowego. Te elementy muszą być ilościowo (dane) - Jaki jest efekt klienta wady? - Wpływ na logistycznego zarządzania części - Wpływ "&"na obsługę części - Wpływ na montaż części - wpływ techniczny we wniosku - Wpływ na niezawodność produktu - Wpływ w perspektywie bezpieczeństwa - regulacja - Jak ważny jest problem?") | O10: -De ce este o problemă? În această secțiune trebuie să înțelegem ce impactul problemei este locul de asamblare și / sau pentru clientul final. Aceste elemente trebuie să fie cuantificate (date) - Care este efectul de client al defectului? - Impactul asupra"&" managementului logistic al părții - Impactul asupra manipularea părții - Impactul asupra ansamblului părții - Impactul tehnic în cerere - Impactul asupra fiabilității produsului - Impactul în termen de siguranță - Regulamentul - Cât de important este pro"&"blema?") | P10: -Почему это является проблемой? В этом разделе нам нужно понять, какое влияние проблема оказывает на сборочный завод и / или на конечного потребителя. Эти элементы должны быть количественно определены (данные) - Каковы последствия дефекта для потребителя? "&"- Влияние на логистическое управление деталью - Влияние на обращение с деталью - Влияние на сборку детали - Техническое влияние при применении - Влияние на надежность продукта - Влияние с точки зрения безопасности - регулирования - Насколько важна пробл"&"ема? ") | Q10: -ทำไม ถึงเป็นปัญหา? ในส่วนนี้เราต้องเข้าใจสิ่งที่ผลกระทบของปัญหาสำหรับการประกอบที่ไลน์ผลิต และ / หรือสำหรับลูกค้าปลายทาง องค์ประกอบเหล่านั้นจะต้องมีการวัดผล (ข้อมูล) - ผลกระทบต่อลูกค้า จากงานบกพร่องคืออะไร ? - ผลกระทบต่อการจัดการโลจิสติกของชินส่วน - ผลกระ"&"ทบต่อการจัดการของชิ้นส่วน - ผลกระทบต่อการประกอบของชิ้นส่วน - ผลกระทบทางเทคนิคในการใช้งาน - ผลกระทบต่อความน่าเชื่อถือของผลิตภัณฑ์ - ผลกระทบในด้านความปลอดภัย - ข้อกำหนด - ปัญหามีความสำคัญอย่างไร") | R10: -O niçin bir problem olsun ki? Bu bölümde problemin darbe montaj sitenin ve / veya nihai Müşteri için ne olduğunu anlamak gerekir. Bu elementler miktarı gerekir (veri) - defekt Müşteri etkisi nedir? - parçanın lojistik yönetimi konusunda Darbe - parçanın k"&"ullanım ile ilgili Etkisi - parçanın montajı Üzerindeki Etkisi - uygulamada teknik etkisi - Ürün güvenilirliği üzerinde etkisi - emniyet vadede Etkisi - regülasyon - Sorun ne kadar önemli?")
A11: [6] | B11: When detected? The objective is to know exactly when the defect has been detected for the first time for the Customer. - date of the detection of the problem - Exact time, hour, minute - Manufacturing shift In addition of the date of detection, the follow"&"ing data must be added for the warranty issues : - Mileage of the car - Date of the registration of the car - Date of notification of the defect to Valeo") | C11: -Lorsqu'il est détecté? L'objectif est de savoir exactement quand le défaut a été détecté pour la première fois pour le client. - date de la détection du problème - Heure exacte, heure, minute - changement de fabrication En plus de la date de détection, le"&"s données suivantes doivent être ajoutées pour les questions de garantie: - Kilométrage de la voiture - La date de l'enregistrement de la voiture - Date de la notification du défaut de Valeo") | D11: -Quando detectado? O objetivo é saber exatamente quando o defeito foi detectado pela primeira vez para o Cliente. - data da detecção do problema - Hora exata; hora, minuto - Turno de fabricação Além da data de detecção, os seguintes dados devem ser adicion"&"ados para os problemas de garantia: - Quilometragem do carro - Data da matrícula do carro - Data de notificação do defeito à Valeo") | E11: -Cuando se detecta? El objetivo es saber exactamente cuando se ha detectado el defecto por primera vez para el cliente. - fecha de la detección del problema - La hora exacta, hora, minuto - turno de fabricación Además de la fecha de detección, los datos si"&"guientes se deben añadir a los problemas de garantía: - Kilometraje del coche - Fecha del registro del coche - Fecha de notificación del defecto a Valeo") | F11: -什么时候探测到的？ 目的是要确切的知道，客户是何时第一次探测到缺陷的。 - 发现问题的日期 - 准确的时间（小时 / 分钟） - 生产班次 除了发现缺陷的日期之外，对于售后来说下面数据需要被考量到： - 车辆的里程数 - 车辆的注册登记日期 - 法雷奥收到缺陷的日期") | G11: -Kdy byl problém nalezen? Cílem je přesně vědět, kdy byl problém poprvé zákazníkem zjištěn. - datum zjištění problému - přesný čas, hodina, minuta zjištění probému - Výrobní směna Kromě času zjištění problému musí být v případě záruční reklamace přidány ty"&"to údaje: - celkové najete kilometry auta - datum registrace auta do provozu - datum oznámení vady Valeu") | H11: -Wann wurde es erkannt? Ziel ist es, genau zu wissen, wann der Mangel zum ersten Mal für die Kunden festgestellt wurde. - Datum der Erfassung des Problems - Genaue Zeit, Stunde, Minute - Fertigungs-Schicht Zusätzlich zum Zeitpunkt der Erkennung, müssen die"&" folgenden Daten für die Gewährleistungsfragen hinzugefügt werden: - Kilometerstand des Autos - Datum der Eintragung des Autos - Datum der Anzeige des Mangels an Valeo") | I11: -Amikor kimutatható? A cél az, hogy pontosan tudja, mikor a hibát észlelte először az ügyfél számára. - időpontja az észlelési probléma - Pontos idő, óra, perc - Gyártási műszak Ezen kívül az észlelés időpontjától, a következő adatokat ki kell egészíteni a"&" garanciális kérdéseket: - futásteljesítménye az autó - időpontja a regisztrációs az autó - időpontja a hiba bejelentésétől a Valeo") | J11: -Ketika terdeteksi? Tujuannya adalah untuk tahu persis kapan cacat telah terdeteksi untuk pertama kalinya bagi Nasabah. - tanggal deteksi masalah - waktu Exact, jam, menit - Manufaktur pergeseran Selain dari tanggal deteksi, data berikut harus ditambahkan "&"untuk masalah garansi: - Jarak tempuh dari mobil - Tanggal pendaftaran mobil - Tanggal pemberitahuan cacat untuk Valeo") | K11: -Quando è stato rilevato? L'obiettivo è quello di sapere esattamente quando è stato rilevato il difetto per la prima volta da parte del Cliente. - data del rilevamento del problema - orario: ore, minuti - turno di produzione Oltre alla data di rilevamento,"&" i seguenti dati devono essere aggiunti per problemi di garanzia: - Chilometraggio della vettura - Data di immatricolazione della vettura - Data di notifica del difetto a Valeo") | L11: -何時発見されたか？ 目的は、不具合がいつお客様に初めて発見されたかを正確に知ることです。 - 問題検出の日時 - 正確な時間、時間、分 - 製造シフト 発見日付の他に、市場不具合に関しては、以下のデータを追加する必要があります。 - 車の走行距離 - 車の登録の日 - Valeoに対する不具合通知日") | M11: -언제 발견되었습니까? 질문의 목적은 언제 고객으로부터 처음 발견되었는지를 정확히 이해하는 것 입니다. - 문제 발견 일자 - 정확한 시간(시 / 분) - 제조 쉬프트 워런티 문제를 위해 아래 정보를 추가로 인지해야 합니다. - 차량 주행거리 - 차량 등록일자 - 문제 통보 일자") | N11: -Kiedy wykryty? Celem jest, aby wiedzieć dokładnie, kiedy wada została wykryta po raz pierwszy dla klienta. - data wykrycia problemu - Zegar, godzina, minuta - przesunięcie Produkcja Ponadto od dnia wykrycia następujące dane muszą być dodane do spraw gwara"&"ncyjnych: - Przebieg samochodu - Data rejestracji samochodu - data zgłoszenia wady do Valeo") | O11: -Când detectat? Obiectivul este de a ști exact când defectul a fost detectat pentru prima dată pentru client. - data detectarea problemei - timp exact, oră, minut - schimbare de fabricație În plus, de la data de detecție, trebuie adăugate următoarele date "&"pentru problemele de garanție: - kilometrajul mașinii - Data înregistrării mașinii - Data notificării defectului Valeo") | P11: -Когда обнаружено? Цель состоит в том, чтобы точно узнать, когда дефект был обнаружен потребителем впервые . - дата обнаружения проблемы - точное время, час, минута - производственная смена В дополнение к дате обнаружения следующие данные должны быть добав"&"лены для гарантийных проблем: - Пробег автомобиля - Дата регистрации автомобиля - дата уведомления Valeo о дефекте ") | Q11: -เมื่อไหร่ ที่ปัญหาถูกตรวจพบ? วัตถุประสงค์คือเพื่อให้ทราบแน่ชัดว่าเมื่อใดที่งานบกพร่องถูกตรวจพบเป็นครั้งแรกสำหรับลูกค้า - วันที่ปัญหาถูกตรวจพบ - เวลาที่แน่นอน , ชั่วโมง, นาที - กะการผลิต นอกจากวันที่ตรวจพบแล้วต้องเพิ่มข้อมูลต่อไปนี้สำหรับปัญหาการรับประกัน:"&" - ระยะไมล์ของรถ - วันที่ของการลงทะเบียนของรถ - วันที่ของการแจ้งเตือนของงานบกพร่องไปที่วาลีโอ") | R11: -Algılandığında? Amaç kusur Müşteri için ilk kez tespit edildi tam olarak ne zaman bilmektir. - bir sorun tespiti tarihi - Tam zamanlı, saat, dakika - İmalat vardiya algılama tarihi ek olarak, aşağıdaki veri garanti sorunları için eklenmelidir: - Arabanın "&"Kilometre - arabanın tescil tarihi - Valeo'ya için defekt Tebliğ tarihi")
A12: [7] | B12: Who detected (name of operator) To know who has detected the defect is key to have the possibility to ask for more precise data. - Name of the person or his registered number - Function of the person, qualification In addition of the date of detection(the"&" personal who detected), the following data, when available, must be added for the warranty issues : - Garage name - End user name") | C12: -Qui détecté (nom de l'opérateur) Pour savoir qui a détecté le défaut est la clé d'avoir la possibilité de demander des données plus précises. - Nom de la personne ou son numéro d'immatriculation - Fonction de la personne, la qualification En plus de la da"&"te de détection, les données suivantes, lorsqu'elles sont disponibles, il faut ajouter les problèmes de garantie: - Nom de Garage - Fin nom d'utilisateur") | D12: -Quem detectou (nome do operador) Saber quem detectou o defeito é fundamental para poder solicitar dados mais precisos. - Nome da pessoa ou seu número registrado - Função da pessoa, qualificação Além da data de detecção, os seguintes dados, quando disp"&"oníveis, devem ser adicionados para os problemas de garantia: - Nome da garagem - Nome do usuário final") | E12: -Quien detectó (nombre del operador) Para saber quién ha detectado el defecto es la clave para tener la posibilidad de solicitar los datos más precisos. - Nombre de la persona o su número de registro - Función de la persona, calificación Además de la fecha"&" de detección, los datos siguientes, cuando estén disponibles, se deben añadir a los problemas de garantía: - Nombre del garaje - Nombre de usuario final") | F12: -谁探测到的（操作员工的名字）? 知道是谁探测到的缺陷，是可能继续询问到更准确数据的关键。 - 人员的姓名或他的工号 - 人员的职能，资质 除了发现缺陷的人员之外，如果有可能，下面数据必须加入到售后的事故中来： - 4S店名称 - 终端使用者姓名") | G12: -Kdo problém našel? (jméno operátora) Musíme vědět, kdo problém nalezl - to je klíčové, abychom se ho mohli vyptat na další důležité informace a data. - Jméno osoby nebo jeho číslo zaměstnance - Funkce osoby, kvalifikace Kromě osoby která nalezla problém m"&"usí být v případě záruční reklamace přidány tyto údaje: - jméno servisu - jméno koncového uživatele (řidiče)") | H12: -Wer hat es erkannt (Name des Bedieners) Zu wissen, wer den Fehler erkannt hat, ist der Schlüssel, um nach genaueren Daten zu fragen. - Name der Person oder seine Registriernummer - Funktion der Person, Qualifikation Zusätzlich zum Zeitpunkt der Erkennung,"&" die folgenden Daten, wenn vorhanden, müssen für Gewährleistungsfragen hinzugefügt werden: - Name der Werkstatt - Name des Endnutzers ") | I12: -Ki mutatható ki (neve operátor) Ahhoz, hogy tudjuk, ki a hiányosságot kulcsfontosságú a lehetőséget, hogy kérjen pontosabb adatokat. - A személy neve vagy bejegyzett száma - Funkció a személy, végzettség Ezen kívül az észlelés időpontjától, a következő ad"&"atokat, amennyiben azok rendelkezésre kell egészíteni a garanciális ügyek: - Garázs neve - Vége felhasználói név") | J12: -Yang terdeteksi (nama operator) Untuk mengetahui siapa yang telah mendeteksi cacat adalah kunci untuk memiliki kemungkinan untuk meminta data yang lebih tepat. - Nama orang atau nomor yang terdaftar nya - Fungsi dari orang tersebut, kualifikasi Selain dar"&"i tanggal deteksi, data berikut, bila tersedia, harus ditambahkan untuk masalah garansi: - nama Garage - Akhir nama pengguna") | K12: -Chi ha rilevato il problema (nome dell'operatore) Conoscere chi ha rilevato il difetto è indispensabile per avere la possibilità di richiedere dati più precisi. - Nome della persona o suo identificativo - Funzione, qualifica della persona Inoltre, la pers"&"ona che ha rilevato il problema, deve aggiungere i seguenti dati per problemi di garanzia ove disponibili: - Nome officina di riparazione - Nome utente finale") | L12: -誰が発見したか（オペレータの名前） 誰が不具合を発見したか知る事は更なる詳細を知るための重要な手がかりです - 名前、電話番号等 - その人の職種やタイトル発見日時の他、市場不具合に関しては、情報ある場合は、次のデータを加える事が望ましい。 - Dealer詳細 - エンドユーザ名") | M12: -검출자 (이름)? 누가 문제를 발견했는지를 아는 것은 더 정확한 정보를 얻기 위해 필수 사항입니다. - 발견자 이름 / 사번 - 발견자 소속팀 / 자격 발견 일자와 마찬가지로, 워런티 문제 대응을 위해 아래 정보를 추가적으로 인지해야 합니다. - 수리처 - 차량 소유주") | N12: -Który wykryto (nazwa operatora) Aby dowiedzieć się, który wykrył wadę jest kluczem, aby mieć możliwość poproszenia o bardziej precyzyjne dane. - Imię i nazwisko osoby lub jego numer rejestrowy - Funkcja osoby, kwalifikacje Ponadto od dnia wykrycia, następ"&"ujące dane, jeśli są dostępne, należy dodać do spraw gwarancyjnych: - nazwa Garaż - nazwa użytkownika końcowego") | O12: -Cine a detectat (numele operatorului) Pentru a afla cine a detectat defectul este cheia pentru a avea posibilitatea de a solicita date mai precise. - Numele persoanei sau numărul său înregistrat - funcția persoanei, calificarea În plus, de la data detectă"&"rii, următoarele date, atunci când sunt disponibile, trebuie să fie adăugate pentru problemele de garanție: - numele de garaj - Numele utilizatorului final") | P12: -Кто обнаружил (имя оператора) Чтобы узнать, кто обнаружил дефект, необходимо иметь возможность запросить более точные данные. - Имя человека или его регистрирационный номер - должность человека, его/ее квалификация В дополнение к данной информации следую"&"щие данные, если таковые имеются, должны быть добавлены для гарантийных проблем: - название дилерского центра - имя конечного пользователя") | Q12: -ใคร คือผู้ตรวจพบ (ชื่อพนักงาน) เพื่อทราบว่าใครเป็นผู้ตรวจพบข้อบกพร่องซึ่งเป็นกุญแจสำคัญที่มีความเป็นไปได้ที่จะขอข้อมูลที่แม่นยำมากขึ้น - ชื่อบุคคล หรือรหัสพนักงาน ของผู้ตรวจพบ - แผนก , หน่วยงาน ของผู้ตรวจพบ นอกจากบุคคลผู้ตรวจพบแล้วจะต้องเพิ่มข้อมูลต่อไปนี"&"้สำหรับปัญหาการรับประกัน: - ชื่ออู่ซ่อมรถ - ชื่อลูกค้าผู้งานใช้ปลายทาง") | R12: -tespit edilen (operatörün ismi) kusur tespit etti kim olduğunu bilmek daha kesin veriler isteyecek olanağına sahip anahtarıdır. - kişinin adı veya onun kayıtlı numara - kişinin İşlevi, yeterlilik algılama tarihi ek olarak, aşağıdaki bilgileri mevcut, gara"&"nti sorunları için eklenmelidir: - Garaj adı - Son kullanıcı adı")
A13: [8] | B13: Where detected? - Plant name or Garage name - Assembly line name - Step of the process of assembly including step before and after (reception, warehouse, subassembly, assembly, test, warehouse, logistic, garage, field…)") | C13: -En cas de détection? - Nom de la plante ou le nom Garage - le nom de la ligne Assemblée - l'étape du processus d'assemblage comprenant l'étape avant et après (réception, entrepôt, sous-ensemble, l'assemblage, test, entrepôt, logistique, garage, terrain .."&".)") | D13: -Onde detectado? - Nome da planta ou nome da concessionária - Nome da linha de montagem - Etapa do processo de montagem incluindo a etapa antes e depois (recepção, armazém, submontagem, montagem, teste, armazém, logística, concessionária, campo ...)") | E13: -Cuando se detecta? - Nombre de la planta o el nombre de Garaje - Nombre de la línea de ensamble - Paso del proceso de ensamblaje incluyendo paso antes y después (recepción, almacén, subconjunto, conjunto, prueba, almacén, logística, garaje, campo ...)") | F13: -在哪里探测到的？ - 工厂或4S店名称 - 装配线名称 - 装配工艺的步骤，包括之前和之后（收货区，仓库，下级装配，装配，测试，仓库，物流，4S店，市场…）""") | G13: -Kde byl problém nalezen? - název výrobního závodu nebo servisu - název montážní linky - krok procesu montáže včetně předchozího a následujícího montážního kroku (příjem, sklad, předmontáž, montáž, testy, sklad, logistická platforma, servis, pole...)") | H13: -Wo erkannt? - Name des Produktionswerkes oder der Werkstatt - Name der Montagelinie - Prozessschritt des Zusammenbaus einschließlich der Stufe davor und danach (Empfang, Lager, Unterbaugruppe, Test, Lager, Logistik, Garage, FIELD ...)") | I13: -Amennyiben észlel? - Növényi nevét vagy garázs neve - Futószalagon neve - lépés a folyamat a szerelvény, beleértve a lépés előtt és után (vétel, raktár, alegység, szerkezeti egység, vizsgálat, raktár, logisztikai, garázs, mező ...)") | J13: -Dimana terdeteksi? - Nama Tanaman atau nama Garage - Nama jalur Majelis - Langkah dari proses perakitan termasuk langkah sebelum dan sesudah (penerimaan, gudang, subassembly, perakitan, pengujian, gudang, logistik, garasi, bidang ...)") | K13: -Dove è stato rilevato? - Nome dello stabilimento o dell'Officina di riparazione - Nome della linea di assemblaggio - Fase di assemblaggio con indicazione dello step di processo prima e dopo (accettazione arrivi, magazzino, semilavorato, test, logistica, o"&"fficina di riparazione, garanzia dal campo ...)") | L13: -どこで発見されましたか？ - 工場名あるいはDealer名 - 組立ラインの名前 - 生産ラインのどの工程での発見か。その前後の工程情報も含めて（受入、倉庫、サブアセンブリ、アセンブリ、テスト、倉庫、ロジスティック、ガレージ、フィールド...）") | M13: -발견 장소? - 공장명 또는 수리처 - 발견 공정명(공정 전 / 후 명 포함) - 입고, 창고, 부분조립, 조립, 시험, 창고, 물류, 필드...)") | N13: -Gdzie wykryto? - nazwa roślin lub nazwa Garaż - nazwa Linia montażowa - Etap procesu montażu włącznie krok przed i po (recepcja, magazyn, podzespół, zespół, testy, magazyn, logistyka, garaż, boisko ...)") | O13: -În cazul în care detectat? - numele plantelor sau numele de garaj - numele liniei de asamblare - Etapa procesului de asamblare, inclusiv pas înainte și după (recepție, depozit, subansamblu, ansamblu, testare, depozit, logistica, garaj, teren ...)") | P13: -Где обнаружено? - Наименование завода-потребителя или дилера - Наименование сборочной линии - Шаг сборочного процесса, включая стадии до и после (поступление, складское хранение, подсбор, сборка, испытания, транспортировка, дилерский центр, гарантия ...)") | Q13: -ที่ไหน ที่ปัญหาถูกตรวจพบ? - ชื่อโรงงานหรือชื่ออู่ซ่อมรถ - ชื่อไลน์การประกอบ - ขั้นตอนของกระบวนการประกอบรวมทั้งขั้นตอนก่อนและหลัง (การรับชิ้นส่วน, คลังสินค้า, การประกอบย่อย, การประกอบ, การทดสอบ, คลังจัดเก็บสินค้า, โลจิสติกส์, โรงรถ, สนามจอดรถ เป็นต้น)") | R13: -Nerede algılandı? - Bitki adı veya Garaj adı - Montaj hattı adı - Montaj öncesi ve sonrası aşamaları içeren sürecin Adım (resepsiyon, depo, alt montaj, montaj, test, depo, lojistik, garaj, alan ...)")
A14: [9] | B14: How detected? The way and the circumstances the defect has been detected is key to understand why the Valeo process did not detect the defect internally - Operation done to detect the defect - Reference to the work instruction when relevant - Type of tool"&" or machine used to detect the defect - Process parameters including distance, time to detect visually the problem, limits or master samples used - Environmental conditions such as light, temperature, ambient noise…") | C14: -Comment détecter? La manière et les circonstances, le défaut a été détecté est la clé pour comprendre pourquoi le processus Valeo n'a pas détecté le défaut interne - Opération effectuée pour détecter le défaut - Référence à l'instruction de travail le cas"&" échéant - Type d'outil ou d'une machine utilisée pour détecter le défaut - Les paramètres de traitement, y compris la distance, le temps de détecter visuellement le problème, des limites ou des échantillons de base utilisés - Les conditions environnement"&"ales telles que la lumière, la température, le bruit ambiant ...") | D14: -Como detectado? A forma e as circunstâncias em que o defeito foi detectado são fundamentais para entender por que o processo da Valeo não detectou o defeito internamente - Operação realizada para detectar o defeito - Referência à instrução de trabalho qua"&"ndo relevante - Tipo de ferramenta ou máquina/equipamento usada para detectar o defeito - Parâmetros do processo, incluindo distância, tempo para detectar visualmente o problema, limites ou amostras padrões usadas - Condições ambientais, como luz, tempera"&"tura, ruído ambiente ...") | E14: -¿Cómo se detecta? La forma y las circunstancias que ha sido detectado el defecto es la clave para entender por qué el proceso de Valeo no detectó el defecto internamente - Operación hace para detectar el defecto - Referencia a la instrucción de trabajo cu"&"ando sea pertinente - Tipo de herramienta o máquina que se utiliza para detectar el defecto - Los parámetros del proceso, incluyendo distancia, el tiempo de detectar visualmente el problema, límites o muestras maestras utilizan - Las condiciones ambiental"&"es tales como la luz, la temperatura, el ruido ambiental ...") | F14: -如何探测到的？ 了解探测到该缺陷的方式及环境很关键，是为了理解为什么法雷奥的内部生产过程无法探测到该缺陷 - 检查该缺陷的操作已完成 - 当相关时，参考作业指导书 - 用来探测该缺陷的工装或设备 - 工艺参数，包括距离，目视检查所用的时间，极限样件或标准样件的使用 - 环境条件，如光照，温度，环境噪声等...") | G14: -Jak byl problém nalezen? To, jak a za jakých okolností byl problém nalezen je klíčové k pochopení, proč nebyl problém nalezen interně v procesu Valeo - Provedené operace vedoucí k nalezení problému - Číslo pracovní instrukce, pokud je to relevantní - typ "&"nástroje nebo stroje použitého k nalezení problému - Procesní parametry včetně vzdálenosti, času pro detekci vizualizaci problému, použité limity nebo master vzorky - Podmínky okolního prostředí, jako je světlo, teplota, okolní hluk ...") | H14: -Wie festgestellt? Die Art und Weise und die Umstände wie der Fehler erkannt wurde ist der Schlüssel zu verstehen, warum der Valeo-Prozess den Fehler nicht intern erkannt hat - durchgeführte Arbeitsfolge, um den Fehler zu entdecken - Bezugnahme auf die Arb"&"eitsanweisung, wenn relevant - Werkzeugtyp oder verwendete Maschine, um den Defekt zu detektieren - Prozessparameter einschließlich Entfernung, Zeit zur visuellen Erfassung des Problems, verwendete Grenzmuster - Umweltbedingungen wie Licht, Temperatur, Um"&"gebungsgeräusche ...") | I14: -Hogyan észlel? Az út és a körülmények a hiba észlelése kulcsfontosságú megérteni, hogy miért a Valeo folyamat nem észleli a hibát belsőleg - Operation tenni, hogy észleli a hibát - Hivatkozás a munkautasítás amikor releváns - Milyen szerszám vagy gép észl"&"eli a hibát - Az eljárás paraméterei, beleértve távolságot, időt felismerni vizuálisan a probléma, korlátozza vagy mester használt minták - környezeti feltételektől, mint a fény, hőmérséklet, a környezeti zaj ...") | J14: -Bagaimana terdeteksi? Cara dan keadaan cacat telah terdeteksi adalah kunci untuk memahami mengapa proses Valeo tidak mendeteksi cacat internal - Operasi dilakukan untuk mendeteksi cacat - Referensi instruksi kerja bila relevan - Jenis alat atau mesin yang"&" digunakan untuk mendeteksi cacat - Parameter proses termasuk jarak, waktu untuk mendeteksi secara visual masalah, batasan atau sampel induk yang digunakan - Kondisi lingkungan seperti cahaya, suhu, kebisingan ambient ...") | K14: -Come è stato rilevato? Il modo e le circostanze in cui è stato rilevato il difetto sono necessari per comprendere il motivo per cui il processo Valeo non ha rilevato il difetto internamente - Operazione eseguita per rilevare il difetto - Riferimento alle "&"istruzioni di lavoro se pertinenti - Tipo di utensile o macchina utilizzata per rilevare il difetto - Parametri di processo, ad esempio distanza visiva e tempo per rilevare il problema, limiti o campioni primari utilizzati per il confronto - Condizioni am"&"bientali quali luce, temperatura, rumore ...") | L14: -どのように発見されましたか？ 不具合が発見された方法や環境を知ることは何故Valeo社内で発見されなかったのかを知る為の重要な鍵です。 - 不具合検出の為の作業内容 - 必要に応じて作業指示書との比較 - 不具合検出の為の治工具あるいは設備の種類 - 目視による不具合発見の為の距離や時間設定含めた工程パラメータ、リミットサンプルやOK/NGマスターの使用 - 業務環境、照明、室温、ノイズレベル等") | M14: -발견 방법? 문제를 발견한 방법 및 문제 현상에 대한 발견 방법은 왜 발레오 내부에서 문제를 감지 못했는지를 이해하는 중요 단서입니다. - 작동 중 부적합 검출 - 작업 지침서를 통한 검출 - 지그 또는 설비에 의한 검출 - 길이, 시간등 시각적 문제를 검출하는 공정 파라미터, 한계 또는 마스터 샘플에 의한 검출 - 빛, 온도, 주변 잡음과 같은 환경적인 요소에 의한 검출") | N14: -Jak wykrywane? Sposób i okoliczności została wykryta wada jest kluczem do zrozumienia, dlaczego proces Valeo nie wykrył usterkę wewnętrznie - Działanie zrobić, aby wykryć wadę - Odniesienie do instrukcji pracy, gdy istotne - Typ narzędzia lub maszyny stos"&"owane do wykrywania wad - parametry procesu, takich jak odległość, czas potrzebny do wykrycia wzrokowo problem ograniczenia lub próbki wzorcowe stosowane - warunki środowiska, takie jak światło, temperatura, ... hałasu otoczenia") | O14: -Cum a detectat? Modul și circumstanțele a fost detectată defectul este cheia pentru a înțelege de ce procesul Valeo nu a detectat defectul intern - Operația făcut pentru a detecta defectul - Trimitere la instrucțiunile de lucru atunci când sunt relevante "&"- Tipul de unealtă sau mașină folosită pentru a detecta defectul - parametrii de proces, inclusiv la distanță, timp pentru a detecta vizual problema, limite sau mostre de master utilizate - condițiile de mediu, cum ar fi lumina, temperatura, zgomotul ambi"&"ant ...") | P14: -Как обнаружено? Способ и обстоятельства обнаружения дефекта являются ключевыми для понимания того, почему дефект был не обнаружен внутри процесса Valeo - Какие действия были выполнены для обнаружения дефекта - Ссылка на рабочую инструкцию, если это примен"&"имо - Тип инструмента или оборудования, используемого для обнаружения дефекта - Параметры процесса, включая расстояние, время для визуального обнаружения проблемы, пределы или используемые эталонные образцы - Условия окружающей среды, такие как свет, темп"&"ература, окружающий шум… ") | Q14: -อย่างไร ปัญหาถูกตรวจพบได้วิธีใด? วิธีและสถานการณ์ที่ตรวจพบข้อบกพร่องเป็นกุญแจสำคัญในการทำความเข้าใจว่าเหตุใดกระบวนการของวาลีโอ จึงตรวจไม่พบข้อบกพร่องได้ภายในวาลีโอ - ดำเนินการเพื่อตรวจหาข้อบกพร่อง - การอ้างอิงถึงคู่มือการปฏิบัติงานเมื่อมีความเกี่ยวข้อง - "&"ประเภทของเครื่องมือหรือเครื่องจักรที่ถูกใช้ในการตรวจจับข้อบกพร่อง - พารามิเตอร์กระบวนการรวมถึงระยะทางเวลาในการตรวจจับปัญหาที่มองเห็นได้, ลิมิตหรือตัวอย่างต้นแบบที่ใช้ - สภาพแวดล้อม เช่น แสง, อุณหภูมิ, เสียงรบกวนรอบข้าง เป็นต้น") | R14: -Nasıl tespit? yolu ve kusur tespit edildi koşullar Valeo süreci içten kusur tespit etmedi anlamak için anahtar - Çalışma kusur tespit etmek için yapılan - zaman ilgili iş talimatına Referans - araç veya makine tipi kusuru tespit etmek için kullanılan - me"&"safe, görsel sorunu tespit zamanı da dahil olmak üzere işlem parametrelerinin, sınırları veya ana örnekleri kullanılmıştır - Böyle ışık, sıcaklık, ortam gürültüsü gibi çevresel koşullar ...")
A15: [10] | B15: How many bad parts? - Precise how many bad parts have been found defective at the time of detection in the Customer process? - Precise how it costs when appropriate") | C15: -Combien de pièces de mauvais? - précise combien de mauvaises pièces ont été trouvés défectueux au moment de la détection dans le processus client? - précise comment il en coûte le cas échéant") | D15: -Quantas peças ruins? - Precise quantas peças defeituosas foram consideradas defeituosas no momento da detecção no processo do Cliente? - Precis o custa quando apropriado") | E15: -¿Cuántas partes malas? - Preciso cuántas partes mal se han encontrado defectuoso en el momento de la detección en el proceso de atención al cliente? - Preciso cómo cuesta cuando sea apropiado") | F15: -有多少坏件？ - 统计有多少坏件在客户的检测过程中被发现 - 在适当的时候，统计要产生多少成本") | G15: -Kolik špatných dílů nalezeno? - Upřesni, kolik špatných dílů bylo nalezeno v okamžiku detekce problému u zákazníka? - Upřesni jaké jsou náklady (pokud je to vhodné)") | H15: -Wie viele schlechte Teile? - ​​wie viele fehlerhafte Teile sind zum Zeitpunkt der Erfassung im Kundenprozess gefunden worden? - wie hoch sind die Kosten, falls angemessen") | I15: -Hány rossz részek? - Pontos mennyi rossz alkatrészeket találtak időpontjában hibás kimutatási Ügyfél folyamat? - Pontos, hogyan kerül szükség esetén") | J15: -Berapa banyak bagian yang buruk? - Precise berapa banyak bagian yang buruk telah ditemukan cacat pada saat deteksi dalam proses Pelanggan? - Precise bagaimana harganya saat yang tepat") | K15: -Quanti pezzi difettosi? - Precisare quanti pezzi difettosi sono stati trovati nel momento della rilevazione nel processo Cliente - Precisare, ove appropriato, l'impatto economico") | L15: -不良品の数？ - 顧客ラインにて同時に何個不具合品が発見されたかを正確に？ - 不具合に付随するコストはどれくらいか、必要に応じて") | M15: -부적합 수량? - 부적합 발견시 얼마나 많은 수량의 불량이 발견되었는가? - 부적합 제품의 비용") | N15: -Ile części źle? - Precyzyjne ilu złe części zostały znalezione wadliwy w momencie wykrycia w procesie klienta? - Precyzyjny jak to kosztuje w stosownych przypadkach") | O15: -Câte părți rele? - precis cât de multe părți rele au fost găsite defecte la momentul detectării în procesul de Client? - precis modul în care costurile atunci când este cazul") | P15: -Сколько плохих деталей обнаружено? - Уточните, сколько плохих деталей было обнаружено потребителем в его процессе? - Уточните стоимость плохих деталей, когда это применимо") | Q15: -เท่าไหร่ จำนวนของเสียกี่ชิ้น? - ระบุจำนวนชิ้นส่วนเสียที่พบข้อบกพร่อง ณ เวลาที่ตรวจพบในกระบวนการของลูกค้าอย่างแม่นยำหรือไม่? - กำหนดค่าใช้จ่ายได้อย่างแม่นยำตามความเหมาะสม") | R15: -Kaç kötü parçalar? - Müşteri sürecinde tespiti sırasında kusurlu kaç kötü parça Hassas bulunmuştur? - Hassas o zaman uygun düzgün maliyeti nasıl")
A16: [11] | B16: What is the difference between good and bad parts? The defect must be described as the deviation between a good and a bad part. Focus on the part and not on the customer application or customer process. These data prepare the analysis team to look in the "&"right direction, this definition will be the starting point of the FTA - Description of the problem with clear and precise facts as seen by Valeo") | C16: -Quelle est la différence entre le bien et les mauvaises parties? Le défaut doit être décrit comme l'écart entre une bonne et une mauvaise partie. Focus sur la partie et non sur l'application client ou processus client. Ces données préparent l'équipe d'ana"&"lyse à regarder dans la bonne direction, cette définition sera le point de départ de l'ALE - Description du problème avec des faits clairs et précis vu par Valeo") | D16: -Qual é a diferença entre as peças boas e ruins? O defeito deve ser descrito como o desvio entre uma peça boa e uma peça ruim. Concentre-se na peça e não no aplicativo ou processo do cliente. Esses dados preparam a equipe de análise para olhar na direção c"&"erta, essa definição será o ponto de partida do FTA - Descrição do problema com fatos claros e precisos, vistos pela Valeo") | E16: -¿Cuál es la diferencia entre el bien y partes malas? El defecto debe ser descrito como la desviación entre una buena y una parte mala. Centrarse en la pieza y no en la aplicación cliente o proceso de cliente. Estos datos preparan el equipo de análisis par"&"a mirar en la dirección correcta, esta definición será el punto de partida del TLC - Descripción del problema con hechos claros y precisos, como se ve por Valeo") | F16: -好件与坏件之间的区别？ 缺陷必须被描述为好件和坏件之间的偏差。关注零件本身，而不是客户的应用或客户的过程。这些数据是为分析小组找到正确方向做准备的，这个定义将会是FTA的起始点 - 从法雷奥观点清楚、准确地描述问题") | G16: -Jaký je rozdíl mezi dobrými a špatnými díly? Vada musí být popsána jako odchylka mezi dobrým a špatným dílem. Zaměřte se na díl a ne na zákaznickou aplikaci nebo proces. Tyto údaje pomohou celému týmu se dívat správným směrem při analýze problému, tato de"&"finice bude výchozím bodem pro analýzu FTA - Popis problému s jasnými a přesnými skutečnostmi z pohledu Valea") | H16: -Was ist der Unterschied zwischen guten und schlechten Teilen? Der Fehler muss als Abweichung zwischen einem guten und einem schlechten Teil beschrieben werden. Konzentrieren Sie sich auf das Teil und nicht auf die Kundenanwendung oder Kundenprozess. Diese"&" Daten dienen zur Vorbereitung für das Analyse-Team in der richtigen Richtung zu suchen, diese Definition ist der Ausgangspunkt für die FTA. - Beschreibung des Problems mit klaren und präzisen Fakten aus Valeo Sicht") | I16: -Mi a különbség a jó és rossz részek? A hibát úgy kell leírni, mint a szórás között egy jó és egy rossz része. Fókuszban a részét, és nem az ügyfél alkalmazás vagy az ügyfél folyamatban. Ezek az adatok előkészítése az elemzés csapat nézni a helyes irányba,"&" ez a meghatározás lesz a kiindulási pont a szabadkereskedelmi - A probléma leírása egyértelmű és pontos tények által látott Valeo") | J16: -Apa perbedaan antara baik dan bagian yang buruk? cacat harus digambarkan sebagai deviasi antara yang baik dan bagian yang buruk. Fokus pada bagian dan bukan pada aplikasi pelanggan atau proses pelanggan. Data ini mempersiapkan tim analisis untuk melihat k"&"e arah yang benar, definisi ini akan menjadi titik awal dari FTA - Deskripsi masalah dengan fakta-fakta yang jelas dan tepat seperti yang terlihat oleh Valeo") | K16: -Qual è la differenza tra i pezzi buoni e quelli difettosi? Il difetto deve essere descritto come differenza tra un pezzo buono e uno di scarto. Bisogna focalizzarsi sul pezzo e non sull'applicazione o processo del Cliente. Questi dati guidano il team di a"&"nalisi nella giusta direzione, e questa definizione sarà il punto di inizio dell'FTA - Descrizione del problema con descrizione chiara e precisa dei fatti come visti da Valeo") | L16: -良品と不良品の差は何ですか？ 不具合は良品と不良品の差に基づいて記述されなければならない。顧客使用状況や工程ではなく、製品そのものに焦点をあてること。これらのデータは分析するチームを正しい方向に導くための準備となり、これはFTAのスタートポイントとなる。 - Valeoの観点で見た場合の明瞭で正確な事実に基づいて記述") | M16: -부적합 제품과 정상제품의 차이점은 무엇입니까? 부적합은 반드시 정상 제품과 부적합 제품간의 차이를 설명해야 합니다. 차이점은 고객의 작업 또는 고객의 공정이 아닌 제품에 초점을 맞추어야 합니다. 이 정보는 분석팀이 옳바른 방향으로 부적합을 분석할 수 있게 하며, FTA의 시작점이 될 것 입니다. - 발레오의 시선으로 사실에 기반하여 명확하게 문제 정의가 되어야 합니다. ") | N16: -Jaka jest różnica między dobrymi i złymi częściami? Wada musi być opisana jako odchylenie o dobrych i złych części. Skupić się na części, a nie w aplikacji klienta lub procesu klienta. Dane te przygotowanie zespołu analitycznego spojrzenia we właściwym ki"&"erunku, definicja ta będzie punktem wyjścia FTA - Opis problemu z jasnych i precyzyjnych faktów widzianych przez Valeo") | O16: -Care este diferența dintre bine și rău părți? Defectul trebuie să fie descrisă ca abaterea între o bună și o parte proastă. Focus pe partea și nu pe aplicația client sau procesul de client. Aceste date pregăti echipa de analiză să se uite în direcția core"&"ctă, această definiție va fi punctul de plecare al ALS - Descrierea problemei cu fapte clare și precise văzut de Valeo") | P16: -В чем разница между хорошими и плохими деталями? Дефект должен быть описан как отклонение между хорошей и плохой деталью. Сосредоточьтесь на детали, а не на заявлении клиента или процессе клиента. Эти данные подготовят аналитическую группу к тому, чтобы с"&"мотреть в правильном направлении, это определение станет отправной точкой для FTA. - Описание проблемы с ясными и точными фактами, как это видит Valeo") | Q16: -อะไรคือความแตกต่างระหว่างงานดีและงานเสีย? ข้อบกพร่องต้องอธิบายว่าความเบี่ยงเบนระหว่างงานดีและงานเสีย มุ่งเน้นไปที่ชิ้งานไม่ใช่ในการใช้งานของลูกค้าหรือกระบวนการของลูกค้า ข้อมูลเหล่านี้เตรียมทีมวิเคราะห์เพื่อมองไปในทิศทางที่ถูกต้อง, คำจำกัดความนี้เป็นจุด"&"เริ่มต้นของ FTA - คำอธิบายปัญหาพร้อมข้อเท็จจริงที่ชัดเจนและแม่นยำตามมุมมองของวาลีโอ") | R16: -iyi ve kötü parçaları arasındaki fark nedir? kusur iyi ve kötü bir parça arasındaki sapma olarak tanımlanabilir olmalıdır. parçası değil müşteri uygulama veya müşteri süreci odaklanın. Bu veriler doğru yönde bakmak için analiz ekibi hazırlamak, bu tanım F"&"TA başlangıç ​​noktasını olacak - net ve kesin gerçeklerle Sorunun açıklaması Valeo'ya tarafından görülen")
A17: [12] | B17: Was part produced in the standard process? Any product or process deviation or rework or operation done by non qualified person must be taken in consideration. If the answer is NO, the deviation must be clearly described and the references of the associat"&"ed documents mentionned. Use tracability information on the part to answer to the question.") | C17: -Faisait partie produit dans le processus standard? Tout écart de produit ou d'un procédé ou une opération reprise effectuée par personne non qualifié doit être pris en considération. Si la réponse est NON, l'écart doit être clairement décrit et les référe"&"nces des documents associés mentionné. Utiliser les informations de tracabilité de la part de répondre à la question.") | D17: -A peça foi produzida no processo padrão? Qualquer desvio de produto ou processo ou retrabalho ou operação feito por pessoa não qualificada deve ser levado em consideração. Se a resposta for NÃO, o desvio deve ser claramente descrito e as referências dos "&"documentos associados mencionadas. Use as informações de rastreabilidade da peça para responder à pergunta.") | E17: -Se produce en parte el proceso estándar? Cualquier desviación de producto o proceso o la reanudación o la operación realizada por una persona no calificada deben ser tomados en consideración. Si la respuesta es NO, la desviación se debe describir con clar"&"idad y las referencias de los documentos asociados mencionado. El uso de información por parte trazabilidad para responder a la pregunta.") | F17: -零件是在标准的过程中生产出来的吗？ 任何产品或过程的偏差或返工或由未认证的员工操作，都必须被考虑到。如果答案是否定的，该偏差必须要被清楚地描述，并且要提到引用的相关的文件。用该零件的追溯性信息来回答问题。") | G17: -Byl díl vyroben ve standardním procesu? Je třeba vzít v úvahu jakoukoliv odchylku výrobku nebo výrobního procesu, opravy (reworks) nebo operace provedené nekvalifikovanou osobou. Je-li odpověď NE, musí být odchylky jasně popsány a zmíněny odkazy na souvis"&"ející dokumenty. K odpovědi na tuto otázku použijte informace o dohledatelnosti (traceability) přítomné na špatném výrobku.") | H17: -Wurde das Teil mit dem Standardprozess hergestellt? Alle Produkt- oder Prozessabweichung oder Nacharbeit oder der Betrieb durch nicht qualifiziertes Personal muss in Betracht gezogen werden. Wenn die Antwort NEIN ist, so muss die Abweichung klar beschrieb"&"en und die Referenzen der zugehörigen Dokumente erwähnt werden. Die Rückverfolgbarkeits-Informationen auf dem Teil sind zur Beantwortung der Frage zu benutzen.") | I17: -Része volt elő a szokásos eljárással? Bármilyen termék vagy folyamat eltérés vagy átdolgozásra vagy művelet történik, nem képesített személy kell figyelembe venni. Ha a válasz nem, az eltérés világosan le kell írni, és a hivatkozások a kapcsolódó dokument"&"umok említettük. Felhasználási tracability információt a része, hogy válaszoljon a kérdésre.") | J17: -Itu bagian diproduksi dalam proses standar? Setiap produk atau proses penyimpangan atau pengerjaan ulang atau operasi yang dilakukan oleh orang non memenuhi syarat harus diambil dalam pertimbangan. Jika jawabannya adalah TIDAK, penyimpangan harus diuraika"&"n secara jelas dan referensi dari dokumen-dokumen terkait mentionned. Gunakan informasi tracability pada bagian untuk menjawab pertanyaan itu.") | K17: -Il pezzo è stato prodotto in un processo standard? Devono essere prese in considerazione deroghe di prodotto o processo e rilavorazioni fatte da personale non qualificato. Se la risposta è NO, il difetto deve essere chiaramente descritto facendo riferimen"&"ti ai documenti di processo associati. Utilizzare le informazioni di rintracciabilità sul pezzo per rispondere alla domanda.") | L17: -製品は通常標準工程で生産されたか？ どのような製品または製造工程における標準逸脱あるいは認定されていないオペレーターによるリワークも考慮する事。もし回答がNOであれば、標準逸脱は正確に記述され関連書類の詳細も同様記述される事。質問に回答する為、トレーサビリティー情報を使用する事") | M17: -제품은 표준 프로세스를 따라 생산되었습니까? 제품 또는 공정의 차이, 또는 리워크, 또는 지정되지 않은 작업자에 의한 생산등을 확인해야 합니다. 만약 답변이 ""아니요"" 라면, 차이점은 명확하게 기술되어야 하며, 관련 문서 또한 확인이 필요합니다. 제품 추적정보를 사용하여, 질문에 답변하시기 바랍니다.") | N17: -Została część produkowana w standardowym procesie? Wszelkie odchylenia produktu lub procesu lub przerobienie lub praca wykonywana przez wykwalifikowaną osobę nie muszą być brane pod uwagę. Jeśli odpowiedź brzmi NIE, odchylenie musi być jasno opisane i odn"&"iesienia do dokumentów związanych mentionned. Wykorzystanie informacji spójność pomiarowa na części, aby odpowiedzieć na to pytanie.") | O17: -A fost parte produs în procesul standard? Orice produs sau proces deviere sau reprelucrate sau operație efectuată de către persoana care nu calificată trebuie să fie luate în considerare. În cazul în care răspunsul este NU, abaterea trebuie să fie descris"&"ă în mod clar și referințele documentelor asociate mentionate. Utilizați informații tracability pe partea de a răspunde la întrebarea.") | P17: -Деталь была произведена в стандартном процессе? Необходимо учитывать любые отклонения продукта или процесса, доработки или операции, выполненные неквалифицированным лицом. Если ответ отрицательный, необходимо четко описать отклонение и указать ссылки на с"&"оответствующие документы. Используйте информацию о прослеживаемости детали, чтобы ответить на вопрос.") | Q17: -ชิ้นงานถูกผลิตภายใต้กระบวนการมาตรฐานหรือไม่? ผลิตภัณฑ์หรือกระบวนการใดๆ ที่เบี่ยงเบนหรือการดำเนินผลิตโดยบุคคลที่ไม่ผ่านการรับรองจะต้องถูกนำมาพิจารณา ถ้าคำตอบคือไม่, ถ้าคำตอบคือไม่ต้องอธิบายความเบี่ยงเบนอย่างชัดเจนและการอ้างอิงของเอกสารที่เกี่ยวข้องที่กล่าว"&"ถึง. ใช้ข้อมูลการตรวจสอบย้อนกลับในส่วนนั้นเพื่อตอบคำถาม.") | R17: -bölüm standart süreçte üretilen mı? olmayan uzman bir kişi tarafından yapılan herhangi bir ürün veya yöntem sapma ya da yeniden işleme veya işletme dikkate alınmalıdır. cevabınız HAYIR ise, sapma açıkça tarif ve ilgili belgelerin referanslar bahsettiğimde"&" edilmelidir. kısmında Kullanım izlenebilirlik bilgileri soruya cevap vermek.")
... A37: [32] | B37: Immediate countermeasures in Customer line Mention immediate countermeasures - Sorting - 100% control - call resident engineer to collect information ") | C37: -contre-mesures immédiates en ligne à la clientèle Mention immédiates contre-mesures - tri - le contrôle à 100% - ingénieur résident d'appel à l'information Collect") | D37: -Contra-medidas imediatas na linha do cliente Mencione contra-medidas imediatas - Seleção - 100% de controle - ligue para o engenheiro residente para coletar informações") | E37: -contramedidas inmediatas en la línea de atención al cliente Mención inmediata adopción de medidas - Clasificación - control del 100% - ingeniero residente llamada a cobro revertido a la información") | F37: -客户端的临时措施 临时措施： - 挑选 - 100％检查 - 通知常驻工程师收集信息") | G37: -Okamžitá protiopatření na lince Zákazníka Popište okamžitá protiopatření - třídění - 100% kontrola - zavolejte rezidentním inženýrům pro sběr informací") | H37: -Sofortige Gegenmaßnahmen in Kunden Linie Erwähnen Sie sofort Gegenmaßnahmen - Sortierung - 100% Kontrolle - Anruf Resident Engineer, Informationen zu sammeln") | I37: -Azonnali ellenintézkedéseket Ügyfél vonal Oldalon azonnali ellenintézkedéseket - Válogatás - 100% kontroll - hívás rezidens mérnök információk összegyűjtésére") | J37: -penanggulangan Segera sejalan Pelanggan Menyebutkan penanggulangan segera - Sortasi - kontrol 100% - panggilan warga insinyur untuk informasi mengumpulkan") | K37: -Contromisure immediate sulla linea del cliente Menzionare le immediate contromisure - Selezione - Controllo al 100% - Chiamare il resident engineer per raccogliere informazioni") | L37: -顧客ラインでの即時対策？ 即時対策について述べよ： - 選別 - 100％コントロール - GREへ連絡しての情報収集") | M37: -고객 라인 즉각 조치 즉각 조치내용에 대해 기입 : - 선별 - 100% 관리 - 정보 수집을 위한 상주원과 연락") | N37: -Natychmiastowe środki zaradcze w linii Klienta Wspomnieć natychmiastowych środków zaradczych - sortowanie - Kontrola 100% - inżynier rezydent wezwanie do zbierania informacji") | O37: -contramăsuri imediate în linie pentru clienți Menționează contramăsuri imediate - Sortare - control 100% - inginer rezident apel la informații collect") | P37: -Незамедлительные контрмеры на линии потребителя Упоминание незамедлительных контрмер: - сортировка - 100% контроль - звонок инженеру-резиденту для сбора информации") | Q37: -มาตรการตอบโต้ทันทีในไลน์ของลูกค้า กล่าวถึงการตอบโต้ทันที - การคัดแยก - การควบคุม 100% - เรียกวิศวกรประจำพื้นที่ลูกค้าเพื่อจำเก็บรวบรวมข้อมูล") | R37: -Müşteri hattında Acil önlemler hemen karşı bahsedin - Sıralama -% 100 kontrol - ödemeli bilgilere çağrı şantiye mühendisi")
B39: -Timeline") | C39: -Chronologie") | D39: -Linha do Tempo") | E39: -Cronología") | F39: -时间轴 ") | G39: -Časová osa") | H39: -Zeitleiste") | I39: -Idővonal") | J39: -Linimasa") | K39: -Sequenza temporale") | L39: -タイムライン") | M39: -타임 라인") | N39: -Oś czasu") | O39: -Cronologie") | P39: -Временная шкала") | Q39: -เส้นเวลา") | R39: -Zaman çizelgesi")
